Workbook

Sheet Tabellino
B1: ="Competizione: " &Evento!B1 -> Competizione: amichevole | AA1: =Evento!B3 & " " & Text(Evento!B2,"dd/mm/yyyy") -> Sanremo 18/11/2023
B2: =Evento!B4 -> Melodic Spikers | G2: =if(I2>I3,1,0)+if(J2>J3,1,0)+if(K2>K3,1,0)+if(L2>L3,1,0)+if(M2>M3,1,0) -> 3 | I2: =Evento!B6 -> 25 | J2: =Evento!B8 -> 25 | K2: =Evento!B10 -> 25 | L2: =Evento!B12 | M2: =Evento!B14
B3: =Evento!B5 -> Rhythmic Blockers | G3: =if(I3>I2,1,0)+if(J3>J2,1,0)+if(K3>K2,1,0)+if(L3>L2,1,0)+if(M3>M2,1,0) -> 0 | I3: =Evento!B7 -> 16 | J3: =Evento!B9 -> 18 | K3: =Evento!B11 -> 22 | L3: =Evento!B13 | M3: =Evento!B15
B5: =Atleti!B1 -> Melodic Spikers | G5: Punti | J5: Battuta | N5: Ricezione | T5: Attacco | AA5: Muro
G6: Tot | H6: V-P | J6: Tot | K6: Err | L6: Pt | N6: Tot | O6: Err | P6: Pos% | Q6: Prf% | R6: Eff% | T6: Tot | U6: Err | V6: Mur | W6: Pt | X6: Pt% | Y6: Eff% | AA6: Pt
B7: =Atleti!B3 -> 19 | C7: =Atleti!C3 | D7: =Atleti!D3 -> Elisa Toffoli | G7: =IF('Gioc A'!$K$11=0,"-",'Gioc A'!$K$11) -> 6 | H7: =if('Gioc A'!K17=0,"-",'Gioc A'!K17) -> 4 | J7: =if('Gioc A'!$H$13=0,"-",'Gioc A'!$H$13) -> 13 | K7: =if('Gioc A'!$G$13=0,"-",'Gioc A'!$G$13) -> 2 | L7: =if('Gioc A'!$B$13=0,"-",'Gioc A'!$B$13) -> 1 | N7: =if('Gioc A'!$H$6=0,"-",'Gioc A'!$H$6) -> 10 | O7: =if('Gioc A'!$G$6=0,"-",'Gioc A'!$G$6) -> - | P7: =if('Gioc A'!$B$9=0,"-",'Gioc A'!$B$9) -> 0.8 | Q7: =If('Gioc A'!$B$6>0,('Gioc A'!$B$6/'Gioc A'!$H$6),"-") -> 0.4 | R7: =If('Gioc A'!$B$8>0,'Gioc A'!$B$8,"-") -> 0.4 | T7: =if('Gioc A'!$H$20=0,"-",'Gioc A'!$H$20) -> 11 | U7: =if('Gioc A'!$G$20=0,"-",'Gioc A'!$G$20) -> - | V7: =if('Gioc A'!$F$20=0,"-",'Gioc A'!$F$20) -> - | W7: =if('Gioc A'!$B$20=0,"-",'Gioc A'!$B$20) -> 5 | X7: =if('Gioc A'!$B$20>0,'Gioc A'!$B$20/'Gioc A'!$H$20,"-") -> 0.45454545 | Y7: =if('Gioc A'!B$22>0,'Gioc A'!B$22,"-") -> 0.45454545 | AA7: =if('Gioc A'!$J$6=0,"-",'Gioc A'!$J$6) -> -
B8: =Atleti!B4 -> 1 | C8: =Atleti!C4 | D8: =Atleti!D4 -> Irene Grandi | G8: =IF('Gioc B'!$K$11=0,"-",'Gioc B'!$K$11) -> 5 | H8: =if('Gioc B'!K17=0,"-",'Gioc B'!K17) -> 4 | J8: =if('Gioc B'!$H$13=0,"-",'Gioc B'!$H$13) -> 1 | K8: =if('Gioc B'!$G$13=0,"-",'Gioc B'!$G$13) -> - | L8: =if('Gioc B'!$B$13=0,"-",'Gioc B'!$B$13) -> - | N8: =if('Gioc B'!$H$6=0,"-",'Gioc B'!$H$6) -> - | O8: =if('Gioc B'!$G$6=0,"-",'Gioc B'!$G$6) -> - | P8: =if('Gioc B'!$B$9=0,"-",'Gioc B'!$B$9) -> - | Q8: =If('Gioc B'!$B$6>0,('Gioc B'!$B$6/'Gioc B'!$H$6),"-") -> - | R8: =If('Gioc B'!$B$8>0,'Gioc B'!$B$8,"-") -> - | T8: =if('Gioc B'!$H$20=0,"-",'Gioc B'!$H$20) -> 6 | U8: =if('Gioc B'!$G$20=0,"-",'Gioc B'!$G$20) -> - | V8: =if('Gioc B'!$F$20=0,"-",'Gioc B'!$F$20) -> - | W8: =if('Gioc B'!$B$20=0,"-",'Gioc B'!$B$20) -> 4 | X8: =if('Gioc B'!$B$20>0,'Gioc B'!$B$20/'Gioc B'!$H$20,"-") -> 0.66666667 | Y8: =if('Gioc B'!B$22>0,'Gioc B'!B$22,"-") -> 0.66666667 | AA8: =if('Gioc B'!$J$6=0,"-",'Gioc B'!$J$6) -> 1
B9: =Atleti!B5 -> 13 | C9: =Atleti!C5 | D9: =Atleti!D5 -> Giorgia Trodani | G9: =IF('Gioc C'!$K$11=0,"-",'Gioc C'!$L$11) -> - | H9: =if('Gioc C'!K17=0,"-",'Gioc C'!K17) -> - | J9: =if('Gioc C'!$H$13=0,"-",'Gioc C'!$H$13) -> - | K9: =if('Gioc C'!$G$13=0,"-",'Gioc C'!$G$13) -> - | L9: =if('Gioc C'!$B$13=0,"-",'Gioc C'!$B$13) -> - | N9: =if('Gioc C'!$H$6=0,"-",'Gioc C'!$H$6) -> - | O9: =if('Gioc C'!$G$6=0,"-",'Gioc C'!$G$6) -> - | P9: =if('Gioc C'!$B$9=0,"-",'Gioc C'!$B$9) -> - | Q9: =If('Gioc C'!$B$6>0,('Gioc C'!$B$6/'Gioc C'!$H$6),"-") -> - | R9: =If('Gioc C'!$B$8>0,'Gioc C'!$B$8,"-") -> - | T9: =if('Gioc C'!$H$20=0,"-",'Gioc C'!$H$20) -> - | U9: =if('Gioc C'!$G$20=0,"-",'Gioc C'!$G$20) -> - | V9: =if('Gioc C'!$F$20=0,"-",'Gioc C'!$F$20) -> - | W9: =if('Gioc C'!$B$20=0,"-",'Gioc C'!$B$20) -> - | X9: =if('Gioc C'!$B$20>0,'Gioc C'!$B$20/'Gioc C'!$H$20,"-") -> - | Y9: =if('Gioc C'!B$22>0,'Gioc C'!B$22,"-") -> - | AA9: =if('Gioc C'!$J$6=0,"-",'Gioc C'!$J$6) -> -
B10: =Atleti!B6 -> 10 | C10: =Atleti!C6 | D10: =Atleti!D6 -> Emma Marrone | G10: =IF('Gioc D'!$K$11=0,"-",'Gioc D'!$K$11) -> 3 | H10: =if('Gioc D'!K17=0,"-",'Gioc D'!K17) -> 2 | J10: =if('Gioc D'!$H$13=0,"-",'Gioc D'!$H$13) -> 3 | K10: =if('Gioc D'!$G$13=0,"-",'Gioc D'!$G$13) -> - | L10: =if('Gioc D'!$B$13=0,"-",'Gioc D'!$B$13) -> 2 | N10: =if('Gioc D'!$H$6=0,"-",'Gioc D'!$H$6) -> 2 | O10: =if('Gioc D'!$G$6=0,"-",'Gioc D'!$G$6) -> - | P10: =if('Gioc D'!$B$9=0,"-",'Gioc D'!$B$9) -> 0.5 | Q10: =If('Gioc D'!$B$6>0,('Gioc D'!$B$6/'Gioc D'!$H$6),"-") -> 0.5 | R10: =If('Gioc D'!$B$8>0,'Gioc D'!$B$8,"-") -> 0.5 | T10: =if('Gioc D'!$H$20=0,"-",'Gioc D'!$H$20) -> 3 | U10: =if('Gioc D'!$G$20=0,"-",'Gioc D'!$G$20) -> 1 | V10: =if('Gioc D'!$F$20=0,"-",'Gioc D'!$F$20) -> - | W10: =if('Gioc D'!$B$20=0,"-",'Gioc D'!$B$20) -> 1 | X10: =if('Gioc D'!$B$20>0,'Gioc D'!$B$20/'Gioc D'!$H$20,"-") -> 0.33333333 | Y10: =if('Gioc D'!B$22>0,'Gioc D'!B$22,"-") -> - | AA10: =if('Gioc D'!$J$6=0,"-",'Gioc D'!$J$6) -> -
B11: =Atleti!B7 -> 11 | C11: =Atleti!C7 -> L | D11: =Atleti!D7 -> Lorendana Bertè | G11: =IF('Gioc E'!$K$11=0,"-",'Gioc E'!$K$11) -> - | H11: =if('Gioc E'!K17=0,"-",'Gioc E'!K17) -> - | J11: =if('Gioc E'!$H$13=0,"-",'Gioc E'!$H$13) -> - | K11: =if('Gioc E'!$G$13=0,"-",'Gioc E'!$G$13) -> - | L11: =if('Gioc E'!$B$13=0,"-",'Gioc E'!$B$13) -> - | N11: =if('Gioc E'!$H$6=0,"-",'Gioc E'!$H$6) -> - | O11: =if('Gioc E'!$G$6=0,"-",'Gioc E'!$G$6) -> - | P11: =if('Gioc E'!$B$9=0,"-",'Gioc E'!$B$9) -> - | Q11: =If('Gioc E'!$B$6>0,('Gioc E'!$B$6/'Gioc E'!$H$6),"-") -> - | R11: =If('Gioc E'!$B$8>0,'Gioc E'!$B$8,"-") -> - | T11: =if('Gioc E'!$H$20=0,"-",'Gioc E'!$H$20) -> - | U11: =if('Gioc E'!$G$20=0,"-",'Gioc E'!$G$20) -> - | V11: =if('Gioc E'!$F$20=0,"-",'Gioc E'!$F$20) -> - | W11: =if('Gioc E'!$B$20=0,"-",'Gioc E'!$B$20) -> - | X11: =if('Gioc E'!$B$20>0,'Gioc E'!$B$20/'Gioc E'!$H$20,"-") -> - | Y11: =if('Gioc E'!B$22>0,'Gioc E'!B$22,"-") -> - | AA11: =if('Gioc E'!$J$6=0,"-",'Gioc E'!$J$6) -> -
B12: =Atleti!B8 -> 9 | C12: =Atleti!C8 | D12: =Atleti!D8 -> Elodie Patrizi | G12: =IF('Gioc F'!$K$11=0,"-",'Gioc F'!$K$11) -> 5 | H12: =if('Gioc F'!K17=0,"-",'Gioc F'!K17) -> 2 | J12: =if('Gioc F'!$H$13=0,"-",'Gioc F'!$H$13) -> 12 | K12: =if('Gioc F'!$G$13=0,"-",'Gioc F'!$G$13) -> 3 | L12: =if('Gioc F'!$B$13=0,"-",'Gioc F'!$B$13) -> 3 | N12: =if('Gioc F'!$H$6=0,"-",'Gioc F'!$H$6) -> - | O12: =if('Gioc F'!$F$6=0,"-",'Gioc F'!$F$6) -> - | P12: =if('Gioc F'!$B$9=0,"-",'Gioc F'!$B$9) -> - | Q12: =If('Gioc F'!$B$6>0,('Gioc F'!$B$6/'Gioc F'!$H$6),"-") -> - | R12: =If('Gioc F'!$B$8>0,'Gioc F'!$B$8,"-") -> - | T12: =if('Gioc F'!$H$20=0,"-",'Gioc F'!$H$20) -> 3 | U12: =if('Gioc F'!$G$20=0,"-",'Gioc F'!$G$20) -> - | V12: =if('Gioc F'!$F$20=0,"-",'Gioc F'!$F$20) -> - | W12: =if('Gioc F'!$B$20=0,"-",'Gioc F'!$B$20) -> 1 | X12: =if('Gioc F'!$B$20>0,'Gioc F'!$B$20/'Gioc F'!$H$20,"-") -> 0.33333333 | Y12: =if('Gioc F'!B$22>0,'Gioc F'!B$22,"-") -> 0.33333333 | AA12: =if('Gioc F'!$J$6=0,"-",'Gioc F'!$J$6) -> 1
B13: =Atleti!B9 -> 5 | C13: =Atleti!C9 | D13: =Atleti!D9 -> Laura Pausini | G13: =IF('Gioc G'!$K$11=0,"-",'Gioc G'!$K$11) -> 5 | H13: =if('Gioc G'!K17=0,"-",'Gioc G'!K17) -> 3 | J13: =if('Gioc G'!$H$13=0,"-",'Gioc G'!$H$13) -> 15 | K13: =if('Gioc G'!$G$13=0,"-",'Gioc G'!$G$13) -> 2 | L13: =if('Gioc G'!$B$13=0,"-",'Gioc G'!$B$13) -> 2 | N13: =if('Gioc G'!$H$6=0,"-",'Gioc G'!$H$6) -> - | O13: =if('Gioc G'!$G$6=0,"-",'Gioc G'!$G$6) -> - | P13: =if('Gioc G'!$B$9=0,"-",'Gioc G'!$B$9) -> - | Q13: =If('Gioc G'!$B$6>0,('Gioc G'!$B$6/'Gioc G'!$H$6),"-") -> - | R13: =If('Gioc G'!$B$8>0,'Gioc G'!$B$8,"-") -> - | T13: =if('Gioc G'!$H$20=0,"-",'Gioc G'!$H$20) -> 2 | U13: =if('Gioc G'!$G$20=0,"-",'Gioc G'!$G$20) -> - | V13: =if('Gioc G'!$F$20=0,"-",'Gioc G'!$F$20) -> - | W13: =if('Gioc G'!$B$20=0,"-",'Gioc G'!$B$20) -> 1 | X13: =if('Gioc G'!$B$20>0,'Gioc G'!$B$20/'Gioc G'!$H$20,"-") -> 0.5 | Y13: =if('Gioc G'!B$22>0,'Gioc G'!B$22,"-") -> 0.5 | AA13: =if('Gioc G'!$J$6=0,"-",'Gioc G'!$J$6) -> 2
B14: =Atleti!B10 -> 18 | C14: =Atleti!C10 | D14: =Atleti!D10 -> Annalisa Scarrone | G14: =IF('Gioc H'!$K$11=0,"-",'Gioc H'!$K$11) -> - | H14: =if('Gioc H'!K17=0,"-",'Gioc H'!K17) -> - | J14: =if('Gioc H'!$H$13=0,"-",'Gioc H'!$H$13) -> - | K14: =if('Gioc H'!$G$13=0,"-",'Gioc H'!$G$13) -> - | L14: =if('Gioc H'!$B$13=0,"-",'Gioc H'!$B$13) -> - | N14: =if('Gioc H'!$H$6=0,"-",'Gioc H'!$H$6) -> - | O14: =if('Gioc H'!$G$6=0,"-",'Gioc H'!$G$6) -> - | P14: =if('Gioc H'!$B$9=0,"-",'Gioc H'!$B$9) -> - | Q14: =If('Gioc H'!$B$6>0,('Gioc H'!$B$6/'Gioc H'!$H$6),"-") -> - | R14: =If('Gioc H'!$B$8>0,'Gioc H'!$B$8,"-") -> - | T14: =if('Gioc H'!$H$20=0,"-",'Gioc H'!$H$20) -> - | U14: =if('Gioc H'!$G$20=0,"-",'Gioc H'!$G$20) -> - | V14: =if('Gioc H'!$F$20=0,"-",'Gioc H'!$F$20) -> - | W14: =if('Gioc H'!$B$20=0,"-",'Gioc H'!$B$20) -> - | X14: =if('Gioc H'!$B$20>0,'Gioc H'!$B$20/'Gioc H'!$H$20,"-") -> - | Y14: =if('Gioc H'!B$22>0,'Gioc H'!B$22,"-") -> - | AA14: =if('Gioc H'!$J$6=0,"-",'Gioc H'!$J$6) -> -
B15: =Atleti!B11 -> 22 | C15: =Atleti!C11 | D15: =Atleti!D11 -> Sara Sorrenti | G15: =IF('Gioc I'!$K$11=0,"-",'Gioc I'!$K$11) -> 7 | H15: =if('Gioc I'!K17=0,"-",'Gioc I'!K17) -> 4 | J15: =if('Gioc I'!$H$13=0,"-",'Gioc I'!$H$13) -> 5 | K15: =if('Gioc I'!$G$13=0,"-",'Gioc I'!$G$13) -> 1 | L15: =if('Gioc I'!$B$13=0,"-",'Gioc I'!$B$13) -> - | N15: =if('Gioc I'!$H$6=0,"-",'Gioc I'!$H$6) -> - | O15: =if('Gioc I'!$G$6=0,"-",'Gioc I'!$G$6) -> - | P15: =if('Gioc I'!$B$9=0,"-",'Gioc I'!$B$9) -> - | Q15: =If('Gioc I'!$B$6>0,('Gioc I'!$B$6/'Gioc I'!$H$6),"-") -> - | R15: =If('Gioc I'!$B$8>0,'Gioc I'!$B$8,"-") -> - | T15: =if('Gioc I'!$H$20=0,"-",'Gioc I'!$H$20) -> 21 | U15: =if('Gioc I'!$G$20=0,"-",'Gioc I'!$G$20) -> 2 | V15: =if('Gioc I'!$F$20=0,"-",'Gioc I'!$F$20) -> 2 | W15: =if('Gioc I'!$B$20=0,"-",'Gioc I'!$B$20) -> 7 | X15: =if('Gioc I'!$B$20>0,'Gioc I'!$B$20/'Gioc I'!$H$20,"-") -> 0.33333333 | Y15: =if('Gioc I'!B$22>0,'Gioc I'!B$22,"-") -> 0.23809524 | AA15: =if('Gioc I'!$J$6=0,"-",'Gioc I'!$J$6) -> -
B16: =Atleti!B12 -> 12 | C16: =Atleti!C12 | D16: =Atleti!D12 -> Veronica Scopelliti | G16: =IF('Gioc J'!$K$11=0,"-",'Gioc J'!$K$11) -> 5 | H16: =if('Gioc J'!K17=0,"-",'Gioc J'!K17) -> 1 | J16: =if('Gioc J'!$H$13=0,"-",'Gioc J'!$H$13) -> 3 | K16: =if('Gioc J'!$G$13=0,"-",'Gioc J'!$G$13) -> 1 | L16: =if('Gioc J'!$B$13=0,"-",'Gioc J'!$B$13) -> - | N16: =if('Gioc J'!$H$6=0,"-",'Gioc J'!$H$6) -> - | O16: =if('Gioc J'!$G$6=0,"-",'Gioc J'!$G$6) -> - | P16: =if('Gioc J'!$B$9=0,"-",'Gioc J'!$B$9) -> - | Q16: =If('Gioc J'!$B$6>0,('Gioc J'!$B$6/'Gioc J'!$H$6),"-") -> - | R16: =If('Gioc J'!$B$8>0,'Gioc J'!$B$8,"-") -> - | T16: =if('Gioc J'!$H$20=0,"-",'Gioc J'!$H$20) -> 10 | U16: =if('Gioc J'!$G$20=0,"-",'Gioc J'!$G$20) -> 2 | V16: =if('Gioc J'!$F$20=0,"-",'Gioc J'!$F$20) -> - | W16: =if('Gioc J'!$B$20=0,"-",'Gioc J'!$B$20) -> 5 | X16: =if('Gioc J'!$B$20>0,'Gioc J'!$B$20/'Gioc J'!$H$20,"-") -> 0.5 | Y16: =if('Gioc J'!B$22>0,'Gioc J'!B$22,"-") -> 0.3 | AA16: =if('Gioc J'!$J$6=0,"-",'Gioc J'!$J$6) -> -
B17: =Atleti!B13 -> 3 | C17: =Atleti!C13 -> L | D17: =Atleti!D13 -> Alessandra Amoroso | G17: =IF('Gioc K'!$K$11=0,"-",'Gioc K'!$K$11) -> - | H17: =if('Gioc K'!K17=0,"-",'Gioc K'!K17) -> -2 | J17: =if('Gioc K'!$H$13=0,"-",'Gioc K'!$H$13) -> - | K17: =if('Gioc K'!$G$13=0,"-",'Gioc K'!$G$13) -> - | L17: =if('Gioc K'!$B$13=0,"-",'Gioc K'!$B$13) -> - | N17: =if('Gioc K'!$H$6=0,"-",'Gioc K'!$H$6) -> 23 | O17: =if('Gioc K'!$G$6=0,"-",'Gioc K'!$G$6) -> 2 | P17: =if('Gioc K'!$B$9=0,"-",'Gioc K'!$B$9) -> 0.69565217 | Q17: =If('Gioc K'!$B$6>0,('Gioc K'!$B$6/'Gioc K'!$H$6),"-") -> 0.17391304 | R17: =If('Gioc K'!$B$8>0,'Gioc K'!$B$8,"-") -> 0.086956522 | T17: =if('Gioc K'!$H$20=0,"-",'Gioc K'!$H$20) -> - | U17: =if('Gioc K'!$G$20=0,"-",'Gioc K'!$G$20) -> - | V17: =if('Gioc K'!$F$20=0,"-",'Gioc K'!$F$20) -> - | W17: =if('Gioc K'!$B$20=0,"-",'Gioc K'!$B$20) -> - | X17: =if('Gioc K'!$B$20>0,'Gioc K'!$B$20/'Gioc K'!$H$20,"-") -> - | Y17: =if('Gioc K'!B$22>0,'Gioc K'!B$22,"-") -> - | AA17: =if('Gioc K'!$J$6=0,"-",'Gioc K'!$J$6) -> -
B18: =Atleti!B14 -> 17 | C18: =Atleti!C14 | D18: =Atleti!D14 -> Carmen Consoli | G18: =IF('Gioc L'!$K$11=0,"-",'Gioc L'!$K$11) -> 11 | H18: =if('Gioc L'!K17=0,"-",'Gioc L'!K17) -> 9 | J18: =if('Gioc L'!$H$13=0,"-",'Gioc L'!$H$13) -> 6 | K18: =if('Gioc L'!$G$13=0,"-",'Gioc L'!$G$13) -> - | L18: =if('Gioc L'!$B$13=0,"-",'Gioc L'!$B$13) -> - | N18: =if('Gioc L'!$H$6=0,"-",'Gioc L'!$H$6) -> 4 | O18: =if('Gioc L'!$G$6=0,"-",'Gioc L'!$G$6) -> - | P18: =if('Gioc L'!$B$9=0,"-",'Gioc L'!$B$9) -> 0.5 | Q18: =If('Gioc L'!$B$6>0,('Gioc L'!$B$6/'Gioc L'!$H$6),"-") -> 0.25 | R18: =If('Gioc L'!$B$8>0,'Gioc L'!$B$8,"-") -> 0.25 | T18: =if('Gioc L'!$H$20=0,"-",'Gioc L'!$H$20) -> 19 | U18: =if('Gioc L'!$G$20=0,"-",'Gioc L'!$G$20) -> 2 | V18: =if('Gioc L'!$F$20=0,"-",'Gioc L'!$F$20) -> - | W18: =if('Gioc L'!$B$20=0,"-",'Gioc L'!$B$20) -> 11 | X18: =if('Gioc L'!$B$20>0,'Gioc L'!$B$20/'Gioc L'!$H$20,"-") -> 0.57894737 | Y18: =if('Gioc L'!B$22>0,'Gioc L'!B$22,"-") -> 0.47368421 | AA18: =if('Gioc L'!$J$6=0,"-",'Gioc L'!$J$6) -> -
B19: =Atleti!B15 -> 4 | C19: =Atleti!C15 | D19: =Atleti!D15 -> Gaia Gozzi | G19: =IF('Gioc M'!$K$11=0,"-",'Gioc M'!$K$11) -> 6 | H19: =if('Gioc M'!K17=0,"-",'Gioc M'!K17) -> 2 | J19: =if('Gioc M'!$H$13=0,"-",'Gioc M'!$H$13) -> 8 | K19: =if('Gioc M'!$G$13=0,"-",'Gioc M'!$G$13) -> 1 | L19: =if('Gioc M'!$B$13=0,"-",'Gioc M'!$B$13) -> 2 | N19: =if('Gioc M'!$H$6=0,"-",'Gioc M'!$H$6) -> 10 | O19: =if('Gioc M'!$G$6=0,"-",'Gioc M'!$G$6) -> 3 | P19: =if('Gioc M'!$B$9=0,"-",'Gioc M'!$B$9) -> 0.5 | Q19: =If('Gioc M'!$B$6>0,('Gioc M'!$B$6/'Gioc M'!$H$6),"-") -> 0.3 | R19: =If('Gioc M'!$B$8>0,'Gioc M'!$B$8,"-") -> - | T19: =if('Gioc M'!$H$20=0,"-",'Gioc M'!$H$20) -> 4 | U19: =if('Gioc M'!$G$20=0,"-",'Gioc M'!$G$20) -> - | V19: =if('Gioc M'!$F$20=0,"-",'Gioc M'!$F$20) -> - | W19: =if('Gioc M'!$B$20=0,"-",'Gioc M'!$B$20) -> 3 | X19: =if('Gioc M'!$B$20>0,'Gioc M'!$B$20/'Gioc M'!$H$20,"-") -> 0.75 | Y19: =if('Gioc M'!B$22>0,'Gioc M'!B$22,"-") -> 0.75 | AA19: =if('Gioc M'!$J$6=0,"-",'Gioc M'!$J$6) -> 1
B20: =Atleti!B16 -> 6 | C20: =Atleti!C16 | D20: =Atleti!D16 -> Francesca Calearo | G20: =IF('Gioc N'!$K$11=0,"-",'Gioc N'!$K$11) -> 3 | H20: =if('Gioc N'!K17=0,"-",'Gioc N'!K17) -> 2 | J20: =if('Gioc N'!$H$13=0,"-",'Gioc N'!$H$13) -> 6 | K20: =if('Gioc N'!$G$13=0,"-",'Gioc N'!$G$13) -> 1 | L20: =if('Gioc N'!$B$13=0,"-",'Gioc N'!$B$13) -> - | N20: =if('Gioc N'!$H$6=0,"-",'Gioc N'!$H$6) -> 4 | O20: =if('Gioc N'!$G$6=0,"-",'Gioc N'!$G$6) -> - | P20: =if('Gioc N'!$B$9=0,"-",'Gioc N'!$B$9) -> 0.75 | Q20: =If('Gioc N'!$B$6>0,('Gioc N'!$B$6/'Gioc N'!$H$6),"-") -> 0.5 | R20: =If('Gioc N'!$B$8>0,'Gioc N'!$B$8,"-") -> 0.5 | T20: =if('Gioc N'!$H$20=0,"-",'Gioc N'!$H$20) -> 12 | U20: =if('Gioc N'!$G$20=0,"-",'Gioc N'!$G$20) -> - | V20: =if('Gioc N'!$F$20=0,"-",'Gioc N'!$F$20) -> - | W20: =if('Gioc N'!$B$20=0,"-",'Gioc N'!$B$20) -> 3 | X20: =if('Gioc N'!$B$20>0,'Gioc N'!$B$20/'Gioc N'!$H$20,"-") -> 0.25 | Y20: =if('Gioc N'!B$22>0,'Gioc N'!B$22,"-") -> 0.25 | AA20: =if('Gioc N'!$J$6=0,"-",'Gioc N'!$J$6) -> -
B21: Totali squadra | G21: =SUM(G7:G19) -> 53 | H21: =if(Squadra!K16=0,"-",Squadra!K16) -> 31 | J21: =SUM(J7:J19) -> 66 | K21: =SUM(K7:K19) -> 10 | L21: =SUM(L7:L19) -> 10 | N21: =SUM(N7:N19) -> 49 | O21: =SUM(O7:O19) -> 5 | P21: =Squadra!B8 -> 0.66037736 | Q21: =if(Squadra!B5>0,Squadra!B5/Squadra!H5,"-") -> 0.28301887 | R21: =if(Squadra!B7>0,Squadra!B7,"-") -> 0.18867925 | T21: =SUM(T7:T19) -> 79 | U21: =SUM(U7:U19) -> 7 | V21: =if(SUM(V7:V19)=0,"-",SUM(V7:V19)) -> 2 | W21: =SUM(W7:W19) -> 38 | X21: =if(Squadra!B19>0,Squadra!B19/Squadra!H19,"-") -> 0.45054945 | Y21: =if(Squadra!B21>0,Squadra!B21,"-") -> 0.37362637 | AA21: =if(SUM(AA7:AA19)=0," -",SUM(AA7:AA19)) -> 5
D22: Punti vinti | E22: Bat | F22: Att | G22: Mur | H22: Er. Av
D23: =if(I$2>0,"Set 1","") -> Set 1 | E23: =if(Squadra!B34>0,Squadra!B34,0) -> 4 | F23: =Squadra!B41 -> 15 | G23: =Squadra!J27 -> 2 | H23: =ABS(E23+F23+G23-I2) -> 4 | J23: =Squadra!K32 -> 21 | K23: =Squadra!G34 -> 3 | L23: =Squadra!B34 -> 4 | N23: =Squadra!H27 -> 12 | O23: =Squadra!G27 -> 1 | P23: =Squadra!B30 -> 0.75 | Q23: =if(Squadra!B27>0,Squadra!B27/Squadra!H27,"-") -> 0.41666667 | T23: =Squadra!H41 -> 23 | U23: =Squadra!G41 -> 3 | V23: =Squadra!J27 -> 2 | W23: =Squadra!B41 -> 15 | X23: =if(Squadra!B41>0,Squadra!B41/Squadra!H41,"-") -> 0.65217391 | AA23: =if(Squadra!J27>0,Squadra!J27,"-") -> 2
D24: =if(J$2>0,"Set 2","") -> Set 2 | E24: =if(Squadra!B56>0,Squadra!B56,0) -> 4 | F24: =Squadra!B63 -> 11 | G24: =Squadra!J49 -> 3 | H24: =ABS(E24+F24+G24-J2) -> 7 | J24: =Squadra!K54 -> 18 | K24: =Squadra!G56 -> 2 | L24: =Squadra!B56 -> 4 | N24: =Squadra!H49 -> 18 | O24: =Squadra!G49 -> 2 | P24: =Squadra!B52 -> 0.5 | Q24: =if(Squadra!B49>0,(Squadra!B49/Squadra!H49),"-") -> 0.11111111 | T24: =Squadra!H63 -> 28 | U24: =Squadra!G63 -> 1 | V24: =Squadra!J49 -> 3 | W24: =Squadra!B63 -> 11 | X24: =if(Squadra!B63>0,Squadra!B63/Squadra!H63,"-") -> 0.39285714 | AA24: =if(Squadra!J49>0,Squadra!J49,"-") -> 3
D25: =if(K$2>0,"Set 3","") -> Set 3 | E25: =if(Squadra!B79>0,Squadra!B79,0) -> 2 | F25: =Squadra!B86 -> 15 | G25: =Squadra!J72 -> 0 | H25: =ABS(E25+F25+G25-K2) -> 8 | J25: =Squadra!K77 -> 17 | K25: =Squadra!G79 -> 6 | L25: =Squadra!B79 -> 2 | N25: =Squadra!H72 -> 23 | O25: =Squadra!G72 -> 2 | P25: =Squadra!B75 -> 0.73913043 | Q25: =if(Squadra!B72>0,Squadra!B72/Squadra!H72,"-") -> 0.34782609 | T25: =Squadra!H86 -> 40 | U25: =Squadra!G86 -> 3 | V25: =Squadra!J72 -> 0 | W25: =Squadra!B86 -> 15 | X25: =if(Squadra!B86>0,Squadra!B86/Squadra!H86,"-") -> 0.375 | AA25: =if(Squadra!J72>0,Squadra!J72,"-") -> -
D26: =if(L$2>0,"Set 4","") | E26: =if(D26<>"",if(Squadra!B102>0,Squadra!B102,0),"") | F26: =if(D26<>"",if(Squadra!B109>0,Squadra!B109,0),"") | G26: =if(D26<>"",if(Squadra!J95>0,Squadra!J95,0),"") | H26: =IF(L2 <> "",ABS(E26+F26+G26-L2),"") | J26: =if(D26<>"",IF(Squadra!H102=0,"0",Squadra!H102),"") | K26: =if(D26<>"",IF(Squadra!G102=0,"0",Squadra!G102),"") | L26: =if(D26<>"",IF(Squadra!G102=0,"0",Squadra!G102),"") | N26: =if(D26<>"",IF(Squadra!H95>0,Squadra!H95,"0"),"") | O26: =if(D26<>"",if(Squadra!G95>0,Squadra!G95,"0"),"") | P26: =if(D26<>"",if(Squadra!B95>0,Squadra!B98,"0"),"") | Q26: =if(D26<>"",if(Squadra!B95>0,Squadra!B95/Squadra!H95,"0"),"") | T26: =if(D26<>"",if(Squadra!H109>0,Squadra!H109,"-"),"") | U26: =if(D26<>"",if(Squadra!G109>0,Squadra!G109,"-"),"") | V26: =if(D26<>"",if(Squadra!J95>0,Squadra!J95,"0"),"") | W26: =if(D26<>"",if(Squadra!B109>0,Squadra!B109,"0"),"") | X26: =if(D26<>"",if(Squadra!B109>0,Squadra!B109/Squadra!H109,"0"),"") | AA26: =if(D26<>"",if(Squadra!J95>0,Squadra!J95,"0"),"")
D27: =If(M2="","","Set 5") | E27: =if(D27<>"",if(Squadra!B125>0,Squadra!B125,0),"") | F27: =if($D$27<>"",if(Squadra!B132>0,Squadra!B132,0),"") | G27: =if(D27<>"",if(Squadra!J118>0,Squadra!J118,"0"),"") | H27: =IF(M2<>"",E27+F27+G27-M2,"") | J27: =if(D27<>"",IF(Squadra!H125=0,"0",Squadra!H125),"") | K27: =if(D27<>"",IF(Squadra!H125=0,"0",Squadra!G125),"") | L27: =if(D27<>"",IF(Squadra!H125=0,"0",Squadra!B125),"") | N27: =if(D27<>"",if(Squadra!H118>0,Squadra!H118,"0"),"") | O27: =if(D27<>"",if(#REF!>0,#REF!,"0"),"") | P27: =if(D27<>"",if(Squadra!B119>0,Squadra!B119,"0"),"") | Q27: =if(D27<>"",if(Squadra!B118>0,Squadra!B118/Squadra!H118,"0"),"") | T27: =if(D27<>"",if(Squadra!H132>0,Squadra!H132,"0"),"") | U27: =if(D27<>"",if(Squadra!G132>0,Squadra!G132,"0"),"") | V27: =if(D27<>"",if(Squadra!J118>0,Squadra!J118,"0"),"") | W27: =if(D27<>"",if(Squadra!B132>0,Squadra!B132,"0"),) | X27: =if(D27<>"",if(Squadra!B132>0,Squadra!B132/Squadra!H132,"0"),"") | AA27: =if(D27<>"",if(Squadra!J118>0,Squadra!J118,"0"),"")
B28: Errori totali | E28: =Squadra!L11-O21 -> 20 | F28: =IF(O21 >0, "+ " & O21 & " ace subiti", "") -> + 5 ace subiti | J28: Invasioni a muro | M28: =Squadra!K5 -> 1 | T28: Err Errori | W28: Pos% Positiva !+#
B29: Errori avversari | E29: =H23+H24+H25+H26+H27 -> 19 | J29: Doppie | M29: =Squadra!K7 -> 1 | T29: Mur Murato | W29: Prf Perfetto
B30: VolleyReportXLS by napo | T30: V-P Vinti-Persi | W30: Eff Efficienza

Sheet Evento
A1: competizione: | B1: amichevole
A2: data: | B2: 45248
A3: luogo: | B3: Sanremo
A4: squadra: | B4: Melodic Spikers
A5: avversari: | B5: Rhythmic Blockers
A6: squadra set1 | B6: 25
A7: avversari set1 | B7: 16
A8: squadra set2 | B8: 25
A9: avversari set2 | B9: 18
A10: squadra set3 | B10: 25
A11: avversari set3 | B11: 22
A12: squadra set4
A13: avversari set4
A14: squadra set5
A15: avversari set5

Sheet Rilevazione
A1: Set 1
B2: 19 | C2: B+ | D2: B+ | E2: B+ | F2: A# | G2: B+ | H2: B= | I2: R# | J2: R# | K2: R! | L2: A#
B3: 5 | C3: M! | D3: M+ | E3: B- | F3: M+ | G3: M# | H3: B+ | I3: B# | J3: B+ | K3: B-
B4: 17 | C4: A+ | D4: A# | E4: A= | F4: A+ | G4: R# | H4: A# | I4: B+ | J4: B+ | K4: B!
B5: 1 | C5: A# | D5: M- | E5: B+ | F5: A+ | G5: A# | H5: A# | I5: P=
B6: 12 | C6: A# | D6: A+ | E6: A= | F6: A# | G6: B+ | H6: B+ | I6: B= | J6: A# | K6: A# | L6: A#
B7: 10 | C7: R- | D7: A# | E7: A= | F7: B# | G7: B# | H7: B+ | I7: A- | J7: M! | K7: R#
B8: 3 | C8: R- | D8: R# | E8: R! | F8: R! | G8: R+ | H8: R=
B9: 4 | C9: B- | D9: B# | E9: B= | F9: B! | G9: A# | H9: A# | I9: M#
A15: Set 2
B16: 19 | C16: R/ | D16: A! | E16: A+ | F16: M! | G16: A# | H16: R- | I16: B- | J16: B/ | K16: B- | L16: A+ | M16: R# | N16: R#
B17: 9 | C17: B+ | D17: B= | E17: M+ | F17: M# | G17: A+ | H17: B+ | I17: B# | J17: B# | K17: B# | L17: B=
B18: 5 | C18: A+ | D18: B+ | E18: B+ | F18: B# | G18: B- | H18: M! | I18: M+ | J18: M+ | K18: M# | L18: B+ | M18: B+ | N18: B+
B19: 17 | C19: R- | D19: A# | E19: A# | F19: A# | G19: A+ | H19: R- | I19: B+ | J19: B+ | K19: B/ | L19: A+ | M19: A# | N19: A+ | O19: R+ | P19: A# | Q19: A#
B20: 1 | C20: M+ | D20: M! | E20: A- | F20: A# | G20: M#
B21: 22 | C21: A+ | D21: M+ | E21: A/ | F21: M- | G21: A+ | H21: A+ | I21: A+ | J21: A+ | K21: M+ | L21: A# | M21: B # | N21: B- | O21: B+ | P21: A# | Q21: A= | R21: A- | S21: A#
B22: 3 | C22: R- | D22: R- | E22: R+ | F22: R+ | G22: R= | H22: R+ | I22: R! | J22: R! | K22: R+
B23: 4 | C23: B/ | D23: R- | E23: R=
A29: Set 3
B30: 19 | C30: B# | D30: B= | E30: A+ | F30: A# | G30: B+ | H30: B+ | I30: M+ | J30: A+ | K30: A+ | L30: M! | M30: B+ | N30: A# | O30: R+ | P30: R! | Q30: R!
B31: 5 | C31: M! | D31: B= | E31: M- | F31: M! | G31: B= | H31: M- | I31: M+ | J31: B- | K31: A#
B32: 6 | C32: A+ | D32: R# | E32: A+ | F32: B+ | G32: B- | H32: A# | I32: A# | J32: A# | K32: A- | L32: A+ | M32: A+ | N32: A- | O32: B= | P32: R- | Q32: R+ | R32: A+ | S32: A+ | T32: A+ | U32: B+ | V32: B+ | W32: B+ | X32: R#
B33: 9 | C33: A+ | D33: A# | E33: B+ | F33: B+ | G33: B= | H33: B+ | I33: B+
B34: 22 | C34: A# | D34: A# | E34: A# | F34: B= | G34: A/ | H34: A! | I34: A# | J34: A= | K34: A+ | L34: B+ | M34: A+ | N34: B+ | O34: A+
B35: 4 | C35: R- | D35: R# | E35: R= | F35: R# | G35: R# | H35: B+ | I35: A# | J35: R+ | K35: A+ | L35: B# | M35: B+ | N35: R+ | O35: R=
B36: 3 | C36: R# | D36: R- | E36: R+ | F36: R+ | G36: R# | H36: R# | I36: R+ | J36: R/
B37: 12 | C37: A+ | D37: M+ | E37: A+ | F37: M+ | G37: A= | H37: M=
B38: 17 | C38: A# | D38: A# | E38: A+ | F38: A= | G38: A#
A43: Set 4
A57: Set 5

Sheet Atleti
A1: squadra: | B1: Melodic Spikers
A2: scheda | B2: num | C2: ruolo | D2: nome
A3: A | B3: 19 | D3: Elisa Toffoli
A4: B | B4: 1 | D4: Irene Grandi
A5: C | B5: 13 | D5: Giorgia Trodani
A6: D | B6: 10 | D6: Emma Marrone
A7: E | B7: 11 | C7: L | D7: Lorendana Bertè
A8: F | B8: 9 | D8: Elodie Patrizi
A9: G | B9: 5 | D9: Laura Pausini
A10: H | B10: 18 | D10: Annalisa Scarrone
A11: I | B11: 22 | D11: Sara Sorrenti
A12: J | B12: 12 | D12: Veronica Scopelliti
A13: K | B13: 3 | C13: L | D13: Alessandra Amoroso
A14: L | B14: 17 | D14: Carmen Consoli
A15: M | B15: 4 | D15: Gaia Gozzi
A16: N | B16: 6 | D16: Francesca Calearo
A18: NOTA: non modificare la colonna scheda

Sheet Grafici squadra
A1: Andamento fondamentali di squadra

Sheet Vinti-Persi Squadra
A1: Punti vinti e persi dalla squadra
B2: Vinti | C2: Persi
A3: Totale | B3: =SUM(B4:B6) -> 53 | C3: =C7+C6+C5+C4 -> 19
A4: Attacco | B4: =Tabellino!W21 -> 38 | C4: =Tabellino!U21 -> 7
A5: Battuta | B5: =Tabellino!L21 -> 10 | C5: =Tabellino!K21 -> 10
A6: Muro | B6: =Tabellino!AA21 -> 5 | C6: =Squadra!K5 -> 1
A7: Palleggio | C7: =Squadra!K7 -> 1
A8: Errori Avv | B8: =Tabellino!E29 -> 19

Sheet Statistiche GIoc
A1: Atleta | B1: 18 | C1: =B1 -> 18 | D1: =C2 -> Annalisa Scarrone
C2: =VLOOKUP(B1, Atleti!$B$3:$D$16, 3, FALSE) -> Annalisa Scarrone
T16: vinti | U16: persi
S17: Battuta | T17: =B60 -> 0 | U17: =G60 -> 0 | V17: VINTI-PERSI
S18: Attacco | T18: =L53 -> 0 | U18: =Q53 -> 0 | V18: =U59 -> 0
S19: Muro | T19: =L60 -> 0 | U19: =M60 -> 0
S20: Palleggio | U20: =M62 -> 0
S21: TOTALE | T21: =SUM(T17:T20) -> 0 | U21: =SUM(U17:U20) -> 0
S23: Ricezione | V23: Attacco
S24: Efficienza | T24: =B55 -> 0 | V24: Efficienza | W24: =L55 -> 0
S25: Positività | T25: =B56 -> 0 | V25: Positività | W25: =L56 -> 0
S26: Ace subiti | T26: =G53 -> 0 | V26: Muri subiti | W26: =P53 -> 0
A50: PARTITA
B51: Ricezione | L51: Attacco
B52: R# | C52: R+ | D52: R! | E52: R- | F52: R/ | G52: R= | H52: Tot | L52: A# | M52: A+ | N52: A! | O52: A- | P52: A/ | Q52: A= | R52: Tot | T52: Riassunto
B53: =COUNTIF(B209:AG213,B52) -> 0 | C53: =COUNTIF(B209:AG213,C52) -> 0 | D53: =COUNTIF(B209:AG213,D52) -> 0 | E53: =COUNTIF(B209:AG213,E52) -> 0 | F53: =COUNTIF(B209:AG213,F52) -> 0 | G53: =COUNTIF(B209:AG213,G52) -> 0 | H53: =SUM(B53:G53) -> 0 | L53: =COUNTIF(B209:AG213,L52) -> 0 | M53: =COUNTIF(B209:AG213,M52) -> 0 | N53: =COUNTIF(B209:AG213,N52) -> 0 | O53: =COUNTIF(B209:AG213,O52) -> 0 | P53: =COUNTIF(B209:AG213,P52) -> 0 | Q53: =COUNTIF(B209:AG213,Q52) -> 0 | R53: =SUM(L53:Q53) -> 0 | T53: Punti | U53: =B60+L53+L60 -> 0
B54: =IF(H53>0,B53/H53,0) -> 0 | C54: =IF(H53>0,C53/H53,0) -> 0 | D54: =IF(H53>0,D53/H53,0) -> 0 | E54: =IF(H53>0,E53/H53,0) -> 0 | F54: =IF(F53>0,F53/H53,0) -> 0 | G54: =IF(G53>0,G53/H53,0) -> 0 | H54: =SUM(B54:G54) -> 0 | L54: =IF(R53>0,L53/R53,0) -> 0 | M54: =IF(R53>0,M53/R53,0) -> 0 | N54: =IF(R53>0,N53/R53,0) -> 0 | O54: =IF(R53>0,O53/R53,0) -> 0 | P54: =IF(R53>0,P53/R53,0) -> 0 | Q54: =IF(R53>0,Q53/R53,0) -> 0 | R54: =SUM(L54:Q54) -> 0 | T54: Errori | U54: =Q53+G60+M60+M62 -> 0
A55: Efficenza | B55: =IF(H53>0,(B53-G53)/H53,0) -> 0 | K55: Efficenza | L55: =IF(R53>0,(L53-Q53)/R53,0) -> 0 | T55: Err. Ric | U55: =G53 -> 0
A56: Positività | B56: =IF(H53>0,(B53+C53+D53)/H53,0) -> 0 | K56: Positività | L56: =IF(R53>0,(L53+M53+N53+O53)/R53,0) -> 0 | T56: Muri sub | U56: =P53 -> 0
T57: Eff. Ric | U57: =B55 -> 0
B58: Battuta | L58: Muro | T58: Eff. Att. | U58: =L55 -> 0
B59: B# | C59: B+ | D59: B! | E59: B- | F59: B/ | G59: B= | H59: Tot | L59: M# | M59: M= | T59: V-P | U59: =U53-U54-U55 -> 0
B60: =COUNTIF(B209:AG213,B59) -> 0 | C60: =COUNTIF(B209:AG213,C59) -> 0 | D60: =COUNTIF(B209:AG213,D59) -> 0 | E60: =COUNTIF(C209:AH213,E59) -> 0 | F60: =COUNTIF(B209:AG213,F59) -> 0 | G60: =COUNTIF(B209:AG213,G59) -> 0 | H60: =SUM(B60:G60) -> 0 | L60: =COUNTIF(B209:AG213,L59) -> 0 | M60: =COUNTIF(B209:AG213,M59) -> 0
B61: =IF(H60>0,B60/H60,0) -> 0 | C61: =IF(H60>0,C60/H60,0) -> 0 | D61: =IF(H60>0,D60/H60,0) -> 0 | E61: =IF(I60>0,E60/I60,0) -> 0 | F61: =IF(H60>0,F60/H60,0) -> 0 | G61: =IF(H60>0,G60/H60,0) -> 0 | H61: =SUM(B61:G61) -> 0
A62: Efficenza | B62: =IF(H60>0,(B60-G60)/H60,0) -> 0 | L62: P= | M62: =COUNTIF(B209:AG213,L62) -> 0
A63: Efficacia | B63: =IF(H60>0,(B60+C60)/H60,0) -> 0
B65: Difesa
B66: D# | C66: D+ | D66: D! | E66: D- | F66: D/ | G66: D= | H66: Tot
B67: =COUNTIF(B215:AG219,B66) -> 0 | C67: =COUNTIF(B215:AG219,C66) -> 0 | D67: =COUNTIF(B215:AG219,D66) -> 0 | E67: =COUNTIF(C215:AH219,E66) -> 0 | F67: =COUNTIF(B215:AG219,F66) -> 0 | G67: =COUNTIF(B215:AG219,G66) -> 0 | H67: =SUM(B67:G67) -> 0
B68: =IF(H67>0,B67/H67,0) -> 0 | C68: =IF(H67>0,C67/H67,0) -> 0 | D68: =IF(H67>0,D67/H67,0) -> 0 | E68: =IF(I67>0,E67/I67,0) -> 0 | F68: =IF(H67>0,F67/H67,0) -> 0 | G68: =IF(H67>0,G67/H67,0) -> 0 | H68: =SUM(B68:G68) -> 0
A71: SET1 | N71: SET2 | O71: Ricezione | W71: Muro
B72: Ricezione | K72: Muro | O72: R# | P72: R+ | Q72: R! | R72: R- | S72: R/ | T72: R= | U72: Tot | W72: M# | X72: M=
B73: R# | C73: R+ | D73: R! | E73: R- | F73: R/ | G73: R= | H73: Tot | K73: M# | L73: M= | O73: =COUNTIF(B210:AG210,O72) -> 0 | P73: =COUNTIF(B210:AG210,P72) -> 0 | Q73: =COUNTIF(B210:AG210,Q72) -> 0 | R73: =COUNTIF(C210:AH210,R72) -> 0 | S73: =COUNTIF(B210:AG210,S72) -> 0 | T73: =COUNTIF(B210:AG210,T72) -> 0 | U73: =SUM(O73:T73) -> 0 | W73: =COUNTIF(B210:AG210,W72) -> 0 | X73: =COUNTIF(B210:AG210,X72) -> 0
B74: =COUNTIF(B209:AG209,B73) -> 0 | C74: =COUNTIF(B209:AG209,C73) -> 0 | D74: =COUNTIF(B209:AG209,D73) -> 0 | E74: =COUNTIF(C209:AH209,E73) -> 0 | F74: =COUNTIF(B209:AG209,F73) -> 0 | G74: =COUNTIF(B209:AG209,G73) -> 0 | H74: =SUM(B74:G74) -> 0 | K74: =COUNTIF(B209:AG209,K73) -> 0 | L74: =COUNTIF(B209:AG209,L73) -> 0 | O74: =IF(U73>0,O73/U73,0) -> 0 | P74: =IF(U73>0,P73/U73,0) -> 0 | Q74: =IF(U73>0,Q73/U73,0) -> 0 | R74: =IF(V73>0,R73/V73,0) -> 0 | S74: =IF(U73>0,S73/U73,0) -> 0 | T74: =IF(U73>0,T73/U73,0) -> 0 | U74: =SUM(O74:T74) -> 0
B75: =IF(H74>0,B74/H74,0) -> 0 | C75: =IF(H74>0,C74/H74,0) -> 0 | D75: =IF(H74>0,D74/H74,0) -> 0 | E75: =IF(I74>0,E74/I74,0) -> 0 | F75: =IF(H74>0,F74/H74,0) -> 0 | G75: =IF(H74>0,G74/H74,0) -> 0 | H75: =SUM(B75:G75) -> 0 | N75: Efficenza | O75: =IF(U73>0,(O73-T73)/U73,0) -> 0
A76: Efficenza | B76: =IF(H74>0,(B74-G74)/H74,0) -> 0 | N76: Positività | O76: =IF(U73>0,(O73+P73+Q73)/U73,0) -> 0
A77: Positività | B77: =IF(H74>0,(B74+C74+D74)/H74,0) -> 0 | W77: Riassunto
K78: Riassunto | O78: Battuta | W78: Punti | X78: =O80+O87+W73 -> 0
B79: Battuta | K79: Punti | L79: =B81+B88+K74 -> 0 | O79: B# | P79: B+ | Q79: B! | R79: B- | S79: B/ | T79: B= | U79: Tot | W79: Errori | X79: =T87+T80 -> 0
B80: B# | C80: B+ | D80: B! | E80: B- | F80: B/ | G80: B= | H80: Tot | K80: Errori | L80: =G88+G81 -> 0 | O80: =COUNTIF(B210:AG210,O79) -> 0 | P80: =COUNTIF(B210:AG210,P79) -> 0 | Q80: =COUNTIF(B210:AG210,Q79) -> 0 | R80: =COUNTIF(B210:AG210,R79) -> 0 | S80: =COUNTIF(C210:AH210,S79) -> 0 | T80: =COUNTIF(B210:AG210,T79) -> 0 | U80: =SUM(O80:T80) -> 0 | W80: Err. Ric | X80: =T73 -> 0
...

Sheet Istruzioni
A1: Chiunque è libero di adattare, modificare, ridistribuire questo file come meglio crede. L'unica cortesia che si chiede è quella di riportare questa indicazione:: VolleyMatchXLS è un progetto nato da una idea di Maurizio Napolitano
A2: puoi offrirmi un caffè qui
A3: https://www.buymeacoffee.com/napo
A5: Istruzioni sull'utilizzo
A6: (più sotto ci sono le informazioni su come si rilevano i dati)
A7: Le schede necessarie per utilizzare il foglio di calcolo sono:
A8: Atleti
A9: qui vanno inseriti i numeri di maglia e i nomi degli atleti senza modificare nient'altro
A11: Evento
A12: si tratta delle informazioni di base sulla gara svolta.
A13: Sono molto importanti i punteggi in quanto sono quelli che calcolano gli errori avversari.
A14: Il consiglio è di vedere come squadra in casa quella per cui si è rilevato il dato.
... A39: Battuta - simbolo "B"
B40: # punto
B41: + avversario non riceve perfetto'
B42: ! avversario riceve distante da rete ma riesce a giocare'
B43: - avvesario riceve senza problemi
B44: / il pallone della ricezione avversaria torna nel nostro campo
B45: = errore in battuta
A46: Ricezione - simbolo "R"
B47: # perfetta
B48: + buona ma primo tempo difficile da giocare
B49: ! con posizione spostata del palleggiatore
B50: - alzata obbligata
B51: / palla non giocata (oltre rete)
B52: = punto subito
A53: Attacco - simbolo "A"
B54: # punto
B55: + attacco difeso da avversario
B56: ! attacco murato ma recuperato dalla copertura
B57: - attacco difeso con possibilità di gioco in primo tempo da parte avversaria
B58: / attacco murato
B59: = attacco sbagliato (rete, fuori, invasione)
A60: Muro - simbolo "M"
B61: # punto
B62: + passivo
B63: ! murato ma recuperato da avversario
B64: - muro scomposto che permette all'avversario di fare punto
B65: = invasione a muro
A66: Palleggio - simbolo "P"
...

Sheet Squadra
A1: SQUADRA
A2: PARTITA
B3: Ricezione | J3: Muro
B4: R# | C4: R+ | D4: R! | E4: R- | F4: R/ | G4: R= | H4: Tot | J4: M# | K4: M=
B5: =COUNTIF(Rilevazione!C2:AN79,B4) -> 15 | C5: =COUNTIF(Rilevazione!C2:AN79,C4) -> 13 | D5: =COUNTIF(Rilevazione!D2:AO79,D4) -> 7 | E5: =COUNTIF(Rilevazione!C2:AN79,E4) -> 11 | F5: =COUNTIF(Rilevazione!C2:AN79,F4) -> 2 | G5: =COUNTIF(Rilevazione!C2:AN79,G4) -> 5 | H5: =SUM(B5:G5) -> 53 | J5: =COUNTIF(Rilevazione!C2:AN79,J4) -> 5 | K5: =COUNTIF(Rilevazione!C2:AN79,K4) -> 1
B6: =B5/H5 -> 0.28301887 | C6: =C5/H5 -> 0.24528302 | D6: =D5/H5 -> 0.13207547 | E6: =E5/H5 -> 0.20754717 | F6: =F5/H5 -> 0.037735849 | G6: =G5/H5 -> 0.094339623 | H6: =SUM(B6:G6) -> 1
A7: Efficenza | B7: =(B5-G5)/H5 -> 0.18867925 | J7: P= | K7: =COUNTIF(Rilevazione!C2:AN79,J7) -> 1
A8: Positività | B8: =(B5+C5+D5)/H5 -> 0.66037736
J9: Riassunto
B10: Battuta | J10: Punti | K10: =B12+B19+J5 -> 56
B11: B# | C11: B/ | D11: B+ | E11: B! | F11: B- | G11: B= | H11: Tot | J11: Errori | K11: =G19+G12+K5+K7 -> 20 | L11: =K11+K12 -> 25
B12: =COUNTIF(Rilevazione!C2:AN79,B11) -> 10 | C12: =COUNTIF(Rilevazione!C2:AN79,C11) -> 3 | D12: =COUNTIF(Rilevazione!D2:AO79,D11) -> 35 | E12: =COUNTIF(Rilevazione!C2:AN79,E11) -> 2 | F12: =COUNTIF(Rilevazione!C2:AN79,F11) -> 9 | G12: =COUNTIF(Rilevazione!C2:AN79,G11) -> 11 | H12: =SUM(B12:G12) -> 70 | J12: Err. Ric | K12: =G5 -> 5
B13: =B12/H12 -> 0.14285714 | C13: =C12/H12 -> 0.042857143 | D13: =D12/H12 -> 0.5 | E13: =E12/H12 -> 0.028571429 | F13: =F12/H12 -> 0.12857143 | G13: =G12/H12 -> 0.15714286 | H13: =SUM(B13:G13) -> 1 | J13: Muri sub | K13: =F19 -> 2
A14: Efficenza | B14: =(B12-G12)/H12 -> -0.014285714 | J14: Eff. Ric | K14: =B7 -> 0.18867925
A15: Efficacia | B15: =(B12+C12)/H12 -> 0.18571429 | J15: Eff. Att. | K15: =B21 -> 0.37362637
J16: V-P | K16: =K10-K11-K12 -> 31
B17: Attacco
B18: A# | C18: A+ | D18: A! | E18: A- | F18: A/ | G18: A= | H18: Tot
B19: =COUNTIF(Rilevazione!C2:AN79,B18) -> 41 | C19: =COUNTIF(Rilevazione!C2:AN79,C18) -> 34 | D19: =COUNTIF(Rilevazione!C2:AN79,D18) -> 2 | E19: =COUNTIF(Rilevazione!C2:AN79,E18) -> 5 | F19: =COUNTIF(Rilevazione!C2:AN79,F18) -> 2 | G19: =COUNTIF(Rilevazione!C2:AN79,G18) -> 7 | H19: =SUM(B19:G19) -> 91
B20: =B19/H19 -> 0.45054945 | C20: =C19/H19 -> 0.37362637 | D20: =D19/H19 -> 0.021978022 | E20: =E19/H19 -> 0.054945055 | F20: =F19/H19 -> 0.021978022 | G20: =G19/H19 -> 0.076923077 | H20: =SUM(B20:G20) -> 1
A21: Efficenza | B21: =(B19-G19)/H19 -> 0.37362637
A22: Positività | B22: =(B19+C19+D19+E19)/H19 -> 0.9010989
A24: SET 1
B25: Ricezione | J25: Muro
B26: R# | C26: R+ | D26: R! | E26: R- | F26: R/ | G26: R= | H26: Tot | J26: M# | K26: M=
B27: =COUNTIF(Rilevazione!C2:AN13,B26) -> 5 | C27: =COUNTIF(Rilevazione!C2:AN13,C26) -> 1 | D27: =COUNTIF(Rilevazione!D2:AO13,D26) -> 3 | E27: =COUNTIF(Rilevazione!C2:AN13,E26) -> 2 | F27: =COUNTIF(Rilevazione!C2:AN13,F26) -> 0 | G27: =COUNTIF(Rilevazione!C2:AN13,G26) -> 1 | H27: =SUM(B27:G27) -> 12 | J27: =COUNTIF(Rilevazione!C2:AN13,J26) -> 2 | K27: =COUNTIF(Rilevazione!C2:AN13,K26) -> 0
B28: =B27/H27 -> 0.41666667 | C28: =C27/H27 -> 0.083333333 | D28: =D27/H27 -> 0.25 | E28: =E27/H27 -> 0.16666667 | F28: =F27/H27 -> 0 | G28: =G27/H27 -> 0.083333333 | H28: =SUM(B28:G28) -> 1
A29: Efficenza | B29: =(B27-G27)/H27 -> 0.33333333 | J29: P= | K29: =COUNTIF(Rilevazione!C2:AN13,J29) -> 1
A30: Positività | B30: =(B27+C27+D27)/H27 -> 0.75
J31: Riassunto
B32: Battuta | J32: Punti | K32: =B34+B41+J27 -> 21
B33: B# | C33: B+ | D33: B! | E33: B- | F33: B/ | G33: B= | H33: Tot | J33: Errori | K33: =G41+G34+K29 -> 7
B34: =COUNTIF(Rilevazione!C2:AN13,B33) -> 4 | C34: =COUNTIF(Rilevazione!C2:AN13,C33) -> 12 | D34: =COUNTIF(Rilevazione!D2:AO13,D33) -> 2 | E34: =COUNTIF(Rilevazione!C2:AN13,E33) -> 3 | F34: =COUNTIF(Rilevazione!C2:AN13,F33) -> 0 | G34: =COUNTIF(Rilevazione!C2:AN13,G33) -> 3 | H34: =SUM(B34:G34) -> 24 | J34: Err. Ric | K34: =G27 -> 1
B35: =B34/H34 -> 0.16666667 | C35: =C34/H34 -> 0.5 | D35: =D34/H34 -> 0.083333333 | E35: =E34/H34 -> 0.125 | F35: =F34/H34 -> 0 | G35: =G34/H34 -> 0.125 | H35: =SUM(B35:G35) -> 1 | J35: Muri sub | K35: =F41 -> 0
A36: Efficenza | B36: =(B34-G34)/H34 -> 0.041666667 | J36: Eff. Ric | K36: =B29 -> 0.33333333
A37: Positività | B37: =(B34+C34)/H34 -> 0.66666667 | J37: Eff. Att. | K37: =B43 -> 0.52173913
B39: Attacco
B40: A# | C40: A+ | D40: A! | E40: A- | F40: A/ | G40: A= | H40: Tot
B41: =COUNTIF(Rilevazione!C2:AN13,B40) -> 15 | C41: =COUNTIF(Rilevazione!C2:AN13,C40) -> 4 | D41: =COUNTIF(Rilevazione!C2:AN13,D40) -> 0 | E41: =COUNTIF(Rilevazione!C2:AN13,E40) -> 1 | F41: =COUNTIF(Rilevazione!C2:AN13,F40) -> 0 | G41: =COUNTIF(Rilevazione!C2:AN13,G40) -> 3 | H41: =SUM(B41:G41) -> 23
B42: =B41/H41 -> 0.65217391 | C42: =C41/H41 -> 0.17391304 | D42: =D41/H41 -> 0 | E42: =E41/H41 -> 0.043478261 | F42: =F41/H41 -> 0 | G42: =G41/H41 -> 0.13043478 | H42: =SUM(B42:G42) -> 1
...

Sheet Gioc A
A1: Giocatore N° | B1: =Atleti!B3 -> 19 | C1: =Atleti!D3 -> Elisa Toffoli
M2: SET1
A3: PARTITA | N3: Ricezione | W3: Muro
B4: Ricezione | J4: Muro | N4: R# | O4: R+ | P4: R! | Q4: R- | R4: R/ | S4: R= | T4: Tot | W4: M# | X4: M=
B5: R# | C5: R+ | D5: R! | E5: R- | F5: R/ | G5: R= | H5: Tot | J5: M# | K5: M= | N5: =COUNTIF(B136:AG136,N4) -> 2 | O5: =COUNTIF(B136:AG136,O4) -> 0 | P5: =COUNTIF(B136:AG136,P4) -> 1 | Q5: =COUNTIF(C136:AH136,Q4) -> 0 | R5: =COUNTIF(B136:AG136,R4) -> 0 | S5: =COUNTIF(B136:AG136,S4) -> 0 | T5: =SUM(N5:S5) -> 3 | W5: =COUNTIF(B136:AG136,W4) -> 0 | X5: =COUNTIF(B136:AG136,X4) -> 0
B6: =COUNTIF(B136:AG140,B5) -> 4 | C6: =COUNTIF(B136:AG140,C5) -> 1 | D6: =COUNTIF(B136:AG140,D5) -> 3 | E6: =COUNTIF(B136:AG140,E5) -> 1 | F6: =COUNTIF(B136:AG140,F5) -> 1 | G6: =COUNTIF(B136:AG140,G5) -> 0 | H6: =SUM(B6:G6) -> 10 | J6: =COUNTIF(B136:AG140,J5) -> 0 | K6: =COUNTIF(B136:AG140,K5) -> 0 | N6: =IF(T5>0,N5/T5,0) -> 0.66666667 | O6: =IF(T5>0,O5/T5,0) -> 0 | P6: =IF(T5>0,P5/T5,0) -> 0.33333333 | Q6: =IF(U5>0,Q5/U5,0) -> 0 | R6: =IF(T5>0,R5/T5,0) -> 0 | S6: =IF(T5>0,S5/T5,0) -> 0 | T6: =SUM(N6:S6) -> 1
B7: =IF(H6>0,B6/H6,0) -> 0.4 | C7: =IF(H6>0,C6/H6,0) -> 0.1 | D7: =IF(H6>0,D6/H6,0) -> 0.3 | E7: =IF(H6>0,E6/H6,0) -> 0.1 | F7: =IF(F6>0,F6/H6,0) -> 0.1 | G7: =IF(G6>0,G6/H6,0) -> 0 | H7: =SUM(B7:G7) -> 1 | M7: Efficenza | N7: =IF(T5>0,(N5-S5)/T5,0) -> 0.66666667
A8: Efficenza | B8: =IF(H6>0,(B6-G6)/H6,0) -> 0.4 | J8: P= | K8: =COUNTIF(B136:AG140,J8) -> 0 | M8: Positività | N8: =IF(T5>0,(N5+O5+P5)/T5,0) -> 1
A9: Positività | B9: =IF(H6>0,(B6+C6+D6)/H6,0) -> 0.8 | W9: Riassunto
J10: Riassunto | N10: Battuta | W10: Punti | X10: =N12+N19+W5 -> 2
B11: Battuta | J11: Punti | K11: =B13+B20+J6 -> 6 | N11: B# | O11: B+ | P11: B! | Q11: B- | R11: B/ | S11: B= | T11: Tot | W11: Errori | X11: =S19+S12 -> 1
B12: B# | C12: B/ | D12: B+ | E12: B! | F12: B- | G12: B= | H12: Tot | J12: Errori | K12: =G20+G13+K6+K8 -> 2 | N12: =COUNTIF(B136:AG136,N11) -> 0 | O12: =COUNTIF(B136:AG136,O11) -> 4 | P12: =COUNTIF(B136:AG136,P11) -> 0 | Q12: =COUNTIF(C136:AH136,Q11) -> 0 | R12: =COUNTIF(B136:AG136,R11) -> 0 | S12: =COUNTIF(B136:AG136,S11) -> 1 | T12: =SUM(N12:S12) -> 5 | W12: Err. Ric | X12: =S5 -> 0
B13: =COUNTIF(B136:AG140,B12) -> 1 | C13: =COUNTIF(B136:AG140,C12) -> 1 | D13: =COUNTIF(B136:AG140,D12) -> 7 | E13: =COUNTIF(C136:AH140,E12) -> 0 | F13: =COUNTIF(B136:AG140,F12) -> 2 | G13: =COUNTIF(B136:AG140,G12) -> 2 | H13: =SUM(B13:G13) -> 13 | J13: Err. Ric | K13: =G6 -> 0 | N13: =IF(T12>0,N12/T12,0) -> 0 | O13: =IF(S2>0,O12/T12,0) -> 0 | P13: =IF(T12>0,P12/T12,0) -> 0 | Q13: =IF(U12>0,Q12/U12,0) -> 0 | R13: =IF(S2>0,R12/T12,0) -> 0 | S13: =IF(S2>0,S12/T12,0) -> 0 | T13: =SUM(N13:S13) -> 0 | W13: Muri sub | X13: =R19 -> 0
B14: =IF(H13>0,B13/H13,0) -> 0.076923077 | C14: =IF(H13>0,C13/H13,0) -> 0.076923077 | D14: =IF(H13>0,D13/H13,0) -> 0.53846154 | E14: =IF(I13>0,E13/I13,0) -> 0 | F14: =IF(H13>0,F13/H13,0) -> 0.15384615 | G14: =IF(H13>0,G13/H13,0) -> 0.15384615 | H14: =SUM(B14:G14) -> 1 | J14: Muri sub | K14: =F20 -> 0 | M14: Efficenza | N14: =IF(T12>0,(N12-S12)/T12,0) -> -0.2 | W14: Eff. Ric | X14: =N7 -> 0.66666667
A15: Efficenza | B15: =IF(H13>0,(B13-G13)/H13,0) -> -0.076923077 | J15: Eff. Ric | K15: =B8 -> 0.4 | M15: Positività | N15: =IF(T12>0,(N12+O12)/T12,0) -> 0.8 | W15: Eff. Att. | X15: =N21 -> 1
A16: Efficacia | B16: =IF(H13>0,(B13+C13)/H13,0) -> 0.15384615 | J16: Eff. Att. | K16: =B22 -> 0.45454545
J17: V-P | K17: =K11-K12-K13 -> 4 | N17: Attacco
B18: Attacco | N18: A# | O18: A+ | P18: A! | Q18: A- | R18: A/ | S18: A= | T18: Tot
B19: A# | C19: A+ | D19: A! | E19: A- | F19: A/ | G19: A= | H19: Tot | N19: =COUNTIF(B136:AG136,N18) -> 2 | O19: =COUNTIF(B136:AG136,O18) -> 0 | P19: =COUNTIF(B136:AG136,P18) -> 0 | Q19: =COUNTIF(B136:AG136,Q18) -> 0 | R19: =COUNTIF(B136:AG136,R18) -> 0 | S19: =COUNTIF(B136:AG136,S18) -> 0 | T19: =SUM(N19:S19) -> 2
B20: =COUNTIF(B136:AG140,B19) -> 5 | C20: =COUNTIF(B136:AG140,C19) -> 5 | D20: =COUNTIF(B136:AG140,D19) -> 1 | E20: =COUNTIF(B136:AG140,E19) -> 0 | F20: =COUNTIF(B136:AG140,F19) -> 0 | G20: =COUNTIF(B136:AG140,G19) -> 0 | H20: =SUM(B20:G20) -> 11 | N20: =IF(T19>0,N19/T19,0) -> 1 | O20: =IF(T19>0,O19/T19,0) -> 0 | P20: =IF(T19>0,P19/T19,0) -> 0 | Q20: =IF(T19>0,Q19/T19,0) -> 0 | R20: =IF(T19>0,R19/T19,0) -> 0 | S20: =IF(T19>0,S19/T19,0) -> 0 | T20: =SUM(N20:S20) -> 1
B21: =IF(H20>0,B20/H20,0) -> 0.45454545 | C21: =IF(H20>0,C20/H20,0) -> 0.45454545 | D21: =IF(H20>0,D20/H20,0) -> 0.090909091 | E21: =IF(H20>0,E20/H20,0) -> 0 | F21: =IF(H20>0,F20/H20,0) -> 0 | G21: =IF(H20>0,G20/H20,0) -> 0 | H21: =SUM(B21:G21) -> 1 | M21: Efficenza | N21: =IF(T19>0,(N19-S19)/T19,0) -> 1
A22: Efficenza | B22: =IF(H20>0,(B20-G20)/H20,0) -> 0.45454545 | M22: Positività | N22: =IF(T19>0,(N19+O19+P19+Q19)/T19,0) -> 1
A23: Positività | B23: =IF(H20>0,(B20+C20+D20+E20)/H20,0) -> 1
A25: SET2 | B25: Ricezione | J25: Muro | M25: SET3 | N25: Ricezione | W25: Muro
B26: R# | C26: R+ | D26: R! | E26: R- | F26: R/ | G26: R= | H26: Tot | J26: M# | K26: M= | N26: R# | O26: R+ | P26: R! | Q26: R- | R26: R/ | S26: R= | T26: Tot | W26: M# | X26: M=
B27: =COUNTIF(B137:AG137,B26) -> 2 | C27: =COUNTIF(B137:AG137,C26) -> 0 | D27: =COUNTIF(B137:AG137,D26) -> 0 | E27: =COUNTIF(C137:AH137,E26) -> 1 | F27: =COUNTIF(B137:AG137,F26) -> 1 | G27: =COUNTIF(B137:AG137,G26) -> 0 | H27: =SUM(B27:G27) -> 4 | J27: =COUNTIF(B137:AG137,J26) -> 0 | K27: =COUNTIF(B137:AG137,K26) -> 0 | N27: =COUNTIF(B138:AG138,N26) -> 0 | O27: =COUNTIF(B138:AG138,O26) -> 1 | P27: =COUNTIF(B138:AG138,P26) -> 2 | Q27: =COUNTIF(C138:AH138,Q26) -> 0 | R27: =COUNTIF(B138:AG138,R26) -> 0 | S27: =COUNTIF(B138:AG138,S26) -> 0 | T27: =SUM(N27:S27) -> 3 | W27: =COUNTIF(B138:AG138,W26) -> 0 | X27: =COUNTIF(B138:AG138,X26) -> 0
B28: =IF(H27>0,B27/H27,0) -> 0.5 | C28: =IF(H27>0,C27/H27,0) -> 0 | D28: =IF(H27>0,D27/H27,0) -> 0 | E28: =IF(I27>0,E27/I27,0) -> 0 | F28: =IF(H27>0,F27/H27,0) -> 0.25 | G28: =IF(H27>0,G27/H27,0) -> 0 | H28: =SUM(B28:G28) -> 0.75 | N28: =IF(T27>0,N27/T27,0) -> 0 | O28: =IF(T27>0,O27/T27,0) -> 0.33333333 | P28: =IF(T27>0,P27/T27,0) -> 0.66666667 | Q28: =IF(U27>0,Q27/U27,0) -> 0 | R28: =IF(T27>0,R27/T27,0) -> 0 | S28: =IF(T27>0,S27/T27,0) -> 0 | T28: =SUM(N28:S28) -> 1
A29: Efficenza | B29: =IF(H27>0,(B27-G27)/H27,0) -> 0.5 | M29: Efficenza | N29: =IF(T27>0,(N27-S27)/T27,0) -> 0
A30: Positività | B30: =IF(H27>0,(B27+C27+D27)/H27,0) -> 0.5 | M30: Positività | N30: =IF(T27>0,(N27+O27+P27)/T27,0) -> 1
J31: Riassunto | W31: Riassunto | AM31: vinti | AN31: persi
B32: Battuta | J32: Punti | K32: =B34+B41+J27 -> 1 | N32: Battuta | W32: Punti | X32: =N34+N41+W27 -> 3 | AL32: Battuta | AM32: =B13 -> 1 | AN32: =G13 -> 2
B33: B# | C33: B+ | D33: B! | E33: B- | F33: B/ | G33: B= | H33: Tot | J33: Errori | K33: =G41+G34 -> 0 | N33: B# | O33: B+ | P33: B! | Q33: B- | R33: B/ | S33: B= | T33: Tot | W33: Errori | X33: =S41+S34 -> 1 | AL33: Attacco | AM33: =B20 -> 5 | AN33: =G20 -> 0
B34: =COUNTIF(B137:AG137,B33) -> 0 | C34: =COUNTIF(B137:AG137,C33) -> 0 | D34: =COUNTIF(B137:AG137,D33) -> 0 | E34: =COUNTIF(B137:AG137,E33) -> 2 | F34: =COUNTIF(C137:AH137,F33) -> 1 | G34: =COUNTIF(B137:AG137,G33) -> 0 | H34: =SUM(B34:G34) -> 3 | J34: Err. Ric | K34: =G27 -> 0 | N34: =COUNTIF(B138:AG138,N33) -> 1 | O34: =COUNTIF(B138:AG138,O33) -> 3 | P34: =COUNTIF(C138:AH138,P33) -> 0 | Q34: =COUNTIF(B138:AG138,Q33) -> 0 | R34: =COUNTIF(B138:AG138,R33) -> 0 | S34: =COUNTIF(B138:AG138,S33) -> 1 | T34: =SUM(N34:S34) -> 5 | W34: Err. Ric | X34: =S27 -> 0 | AL34: Muro | AM34: =J6 -> 0 | AN34: =K6 -> 0
B35: =IF($H$34>0,B34/$H$34,0) -> 0 | C35: =IF($H$34>0,C34/$H$34,0) -> 0 | D35: =IF($H$34>0,D34/$H$34,0) -> 0 | E35: =IF($H$34>0,E34/$H$34,0) -> 0.66666667 | F35: =IF($H$34>0,F34/$H$34,0) -> 0.33333333 | G35: =IF($H$34>0,G34/$H$34,0) -> 0 | H35: =SUM(B35:G35) -> 1 | J35: Eff. Ric | K35: =B29 -> 0.5 | N35: =IF($G$69>0,O34/$H$34,0) -> 0 | O35: =IF($G$69>0,Q34/$H$34,0) -> 0 | P35: =IF($G$69>0,R34/$H$34,0) -> 0 | Q35: =IF($G$69>0,S34/$H$34,0) -> 0 | R35: =IF($G$69>0,T34/$H$34,0) -> 0 | S35: =IF($G$69>0,T34/$H$34,0) -> 0 | W35: Eff. Ric | X35: =N29 -> 0 | AL35: Palleggio | AN35: =K8 -> 0
A36: Efficenza | B36: =IF(H34>0,(B34-G34)/H34,0) -> 0 | J36: Eff. Att. | K36: =B43 -> 0.25 | M36: Efficenza | N36: =IF(T34>0,(N34-S34)/T34,0) -> 0 | W36: Eff. Att. | X36: =N43 -> 0.4
A37: Positività | B37: =IF(H34>0,(B34+C34)/H34,0) -> 0 | I37: Muri sub | J37: =F41 -> 0 | M37: Positività | N37: =IF(T34>0,(N34+O34)/T34,0) -> 0.8 | U37: Muri sub | W37: =R41 -> 0
AL38: VINTI-PERSI
B39: Attacco | N39: Attacco | AL39: =K17 -> 4
B40: A# | C40: A+ | D40: A! | E40: A- | F40: A/ | G40: A= | H40: Tot | N40: A# | O40: A+ | P40: A! | Q40: A- | R40: A/ | S40: A= | T40: Tot
B41: =COUNTIF(B137:AG137,B40) -> 1 | C41: =COUNTIF(B137:AG137,C40) -> 2 | D41: =COUNTIF(B137:AG137,D40) -> 1 | E41: =COUNTIF(B137:AG137,E40) -> 0 | F41: =COUNTIF(B137:AG137,F40) -> 0 | G41: =COUNTIF(B137:AG137,G40) -> 0 | H41: =SUM(B41:G41) -> 4 | N41: =COUNTIF(B138:AG138,N40) -> 2 | O41: =COUNTIF(B138:AG138,O40) -> 3 | P41: =COUNTIF(B138:AG138,P40) -> 0 | Q41: =COUNTIF(B138:AG138,Q40) -> 0 | R41: =COUNTIF(B138:AG138,R40) -> 0 | S41: =COUNTIF(B138:AG138,S40) -> 0 | T41: =SUM(N41:S41) -> 5
...

Sheet Gioc B
A1: Giocatore N° | B1: =Atleti!B4 -> 1 | C1: =Atleti!D4 -> Irene Grandi
M2: SET1
A3: PARTITA | N3: Ricezione | W3: Muro
B4: Ricezione | J4: Muro | N4: R# | O4: R+ | P4: R! | Q4: R- | R4: R/ | S4: R= | T4: Tot | W4: M# | X4: M=
B5: R# | C5: R+ | D5: R! | E5: R- | F5: R/ | G5: R= | H5: Tot | J5: M# | K5: M= | N5: =COUNTIF(B136:AG136,N4) -> 0 | O5: =COUNTIF(B136:AG136,O4) -> 0 | P5: =COUNTIF(B136:AG136,P4) -> 0 | Q5: =COUNTIF(C136:AH136,Q4) -> 0 | R5: =COUNTIF(B136:AG136,R4) -> 0 | S5: =COUNTIF(B136:AG136,S4) -> 0 | T5: =SUM(N5:S5) -> 0 | W5: =COUNTIF(B136:AG136,W4) -> 0 | X5: =COUNTIF(B136:AG136,X4) -> 0
B6: =COUNTIF(B136:AG140,B5) -> 0 | C6: =COUNTIF(B136:AG140,C5) -> 0 | D6: =COUNTIF(B136:AG140,D5) -> 0 | E6: =COUNTIF(B136:AG140,E5) -> 0 | F6: =COUNTIF(B136:AG140,F5) -> 0 | G6: =COUNTIF(B136:AG140,G5) -> 0 | H6: =SUM(B6:G6) -> 0 | J6: =COUNTIF(B136:AG140,J5) -> 1 | K6: =COUNTIF(B136:AG140,K5) -> 0 | N6: =IF(T5>0,N5/T5,0) -> 0 | O6: =IF(T5>0,O5/T5,0) -> 0 | P6: =IF(T5>0,P5/T5,0) -> 0 | Q6: =IF(U5>0,Q5/U5,0) -> 0 | R6: =IF(T5>0,R5/T5,0) -> 0 | S6: =IF(T5>0,S5/T5,0) -> 0 | T6: =SUM(N6:S6) -> 0
B7: =IF(H6>0,B6/H6,0) -> 0 | C7: =IF(H6>0,C6/H6,0) -> 0 | D7: =IF(H6>0,D6/H6,0) -> 0 | E7: =IF(H6>0,E6/H6,0) -> 0 | F7: =IF(F6>0,F6/H6,0) -> 0 | G7: =IF(G6>0,G6/H6,0) -> 0 | H7: =SUM(B7:G7) -> 0 | M7: Efficenza | N7: =IF(T5>0,(N5-S5)/T5,0) -> 0
A8: Efficenza | B8: =IF(H6>0,(B6-G6)/H6,0) -> 0 | J8: P= | K8: =COUNTIF(B136:AG140,J8) -> 1 | M8: Positività | N8: =IF(T5>0,(N5+O5+P5)/T5,0) -> 0
A9: Positività | B9: =IF(H6>0,(B6+C6+D6)/H6,0) -> 0 | W9: Riassunto
J10: Riassunto | N10: Battuta | W10: Punti | X10: =N12+N19+W5 -> 3
B11: Battuta | J11: Punti | K11: =B13+B20+J6 -> 5 | N11: B# | O11: B+ | P11: B! | Q11: B- | R11: B/ | S11: B= | T11: Tot | W11: Errori | X11: =S19+S12 -> 0
B12: B# | C12: B/ | D12: B+ | E12: B! | F12: B- | G12: B= | H12: Tot | J12: Errori | K12: =G20+G13+K6+K8 -> 1 | N12: =COUNTIF(B136:AG136,N11) -> 0 | O12: =COUNTIF(B136:AG136,O11) -> 1 | P12: =COUNTIF(B136:AG136,P11) -> 0 | Q12: =COUNTIF(C136:AH136,Q11) -> 0 | R12: =COUNTIF(B136:AG136,R11) -> 0 | S12: =COUNTIF(B136:AG136,S11) -> 0 | T12: =SUM(N12:S12) -> 1 | W12: Err. Ric | X12: =S5 -> 0
B13: =COUNTIF(B136:AG140,B12) -> 0 | C13: =COUNTIF(B136:AG140,C12) -> 0 | D13: =COUNTIF(B136:AG140,D12) -> 1 | E13: =COUNTIF(C136:AH140,E12) -> 0 | F13: =COUNTIF(B136:AG140,F12) -> 0 | G13: =COUNTIF(B136:AG140,G12) -> 0 | H13: =SUM(B13:G13) -> 1 | J13: Err. Ric | K13: =G6 -> 0 | N13: =IF(T12>0,N12/T12,0) -> 0 | O13: =IF(S2>0,O12/T12,0) -> 0 | P13: =IF(T12>0,P12/T12,0) -> 0 | Q13: =IF(U12>0,Q12/U12,0) -> 0 | R13: =IF(S2>0,R12/T12,0) -> 0 | S13: =IF(S2>0,S12/T12,0) -> 0 | T13: =SUM(N13:S13) -> 0 | W13: Muri sub | X13: =R19 -> 0
B14: =IF(H13>0,B13/H13,0) -> 0 | C14: =IF(H13>0,C13/H13,0) -> 0 | D14: =IF(H13>0,D13/H13,0) -> 1 | E14: =IF(I13>0,E13/I13,0) -> 0 | F14: =IF(H13>0,F13/H13,0) -> 0 | G14: =IF(H13>0,G13/H13,0) -> 0 | H14: =SUM(B14:G14) -> 1 | J14: Muri sub | K14: =F20 -> 0 | M14: Efficenza | N14: =IF(T12>0,(N12-S12)/T12,0) -> 0 | W14: Eff. Ric | X14: =N7 -> 0
A15: Efficenza | B15: =IF(H13>0,(B13-G13)/H13,0) -> 0 | J15: Eff. Ric | K15: =B8 -> 0 | M15: Positività | N15: =IF(T12>0,(N12+O12)/T12,0) -> 1 | W15: Eff. Att. | X15: =N21 -> 0.75
A16: Efficacia | B16: =IF(H13>0,(B13+C13)/H13,0) -> 0 | J16: Eff. Att. | K16: =B22 -> 0.66666667
J17: V-P | K17: =K11-K12-K13 -> 4 | N17: Attacco
B18: Attacco | N18: A# | O18: A+ | P18: A! | Q18: A- | R18: A/ | S18: A= | T18: Tot
B19: A# | C19: A+ | D19: A! | E19: A- | F19: A/ | G19: A= | H19: Tot | N19: =COUNTIF(B136:AG136,N18) -> 3 | O19: =COUNTIF(B136:AG136,O18) -> 1 | P19: =COUNTIF(B136:AG136,P18) -> 0 | Q19: =COUNTIF(B136:AG136,Q18) -> 0 | R19: =COUNTIF(B136:AG136,R18) -> 0 | S19: =COUNTIF(B136:AG136,S18) -> 0 | T19: =SUM(N19:S19) -> 4
B20: =COUNTIF(B136:AG140,B19) -> 4 | C20: =COUNTIF(B136:AG140,C19) -> 1 | D20: =COUNTIF(B136:AG140,D19) -> 0 | E20: =COUNTIF(B136:AG140,E19) -> 1 | F20: =COUNTIF(B136:AG140,F19) -> 0 | G20: =COUNTIF(B136:AG140,G19) -> 0 | H20: =SUM(B20:G20) -> 6 | N20: =IF(T19>0,N19/T19,0) -> 0.75 | O20: =IF(T19>0,O19/T19,0) -> 0.25 | P20: =IF(T19>0,P19/T19,0) -> 0 | Q20: =IF(T19>0,Q19/T19,0) -> 0 | R20: =IF(T19>0,R19/T19,0) -> 0 | S20: =IF(T19>0,S19/T19,0) -> 0 | T20: =SUM(N20:S20) -> 1
B21: =IF(H20>0,B20/H20,0) -> 0.66666667 | C21: =IF(H20>0,C20/H20,0) -> 0.16666667 | D21: =IF(H20>0,D20/H20,0) -> 0 | E21: =IF(H20>0,E20/H20,0) -> 0.16666667 | F21: =IF(H20>0,F20/H20,0) -> 0 | G21: =IF(H20>0,G20/H20,0) -> 0 | H21: =SUM(B21:G21) -> 1 | M21: Efficenza | N21: =IF(T19>0,(N19-S19)/T19,0) -> 0.75
A22: Efficenza | B22: =IF(H20>0,(B20-G20)/H20,0) -> 0.66666667 | M22: Positività | N22: =IF(T19>0,(N19+O19+P19+Q19)/T19,0) -> 1
A23: Positività | B23: =IF(H20>0,(B20+C20+D20+E20)/H20,0) -> 1
A25: SET2 | B25: Ricezione | J25: Muro | M25: SET3 | N25: Ricezione | W25: Muro
B26: R# | C26: R+ | D26: R! | E26: R- | F26: R/ | G26: R= | H26: Tot | J26: M# | K26: M= | N26: R# | O26: R+ | P26: R! | Q26: R- | R26: R/ | S26: R= | T26: Tot | W26: M# | X26: M=
B27: =COUNTIF(B137:AG137,B26) -> 0 | C27: =COUNTIF(B137:AG137,C26) -> 0 | D27: =COUNTIF(B137:AG137,D26) -> 0 | E27: =COUNTIF(C137:AH137,E26) -> 0 | F27: =COUNTIF(B137:AG137,F26) -> 0 | G27: =COUNTIF(B137:AG137,G26) -> 0 | H27: =SUM(B27:G27) -> 0 | J27: =COUNTIF(B137:AG137,J26) -> 1 | K27: =COUNTIF(B137:AG137,K26) -> 0 | N27: =COUNTIF(B138:AG138,N26) -> 0 | O27: =COUNTIF(B138:AG138,O26) -> 0 | P27: =COUNTIF(B138:AG138,P26) -> 0 | Q27: =COUNTIF(C138:AH138,Q26) -> 0 | R27: =COUNTIF(B138:AG138,R26) -> 0 | S27: =COUNTIF(B138:AG138,S26) -> 0 | T27: =SUM(N27:S27) -> 0 | W27: =COUNTIF(B138:AG138,W26) -> 0 | X27: =COUNTIF(B138:AG138,X26) -> 0
B28: =IF(H27>0,B27/H27,0) -> 0 | C28: =IF(H27>0,C27/H27,0) -> 0 | D28: =IF(H27>0,D27/H27,0) -> 0 | E28: =IF(I27>0,E27/I27,0) -> 0 | F28: =IF(H27>0,F27/H27,0) -> 0 | G28: =IF(H27>0,G27/H27,0) -> 0 | H28: =SUM(B28:G28) -> 0 | N28: =IF(T27>0,N27/T27,0) -> 0 | O28: =IF(T27>0,O27/T27,0) -> 0 | P28: =IF(T27>0,P27/T27,0) -> 0 | Q28: =IF(U27>0,Q27/U27,0) -> 0 | R28: =IF(T27>0,R27/T27,0) -> 0 | S28: =IF(T27>0,S27/T27,0) -> 0 | T28: =SUM(N28:S28) -> 0
A29: Efficenza | B29: =IF(H27>0,(B27-G27)/H27,0) -> 0 | M29: Efficenza | N29: =IF(T27>0,(N27-S27)/T27,0) -> 0
A30: Positività | B30: =IF(H27>0,(B27+C27+D27)/H27,0) -> 0 | M30: Positività | N30: =IF(T27>0,(N27+O27+P27)/T27,0) -> 0
J31: Riassunto | W31: Riassunto | AN31: vinti | AO31: persi
B32: Battuta | J32: Punti | K32: =B34+B41+J27 -> 2 | N32: Battuta | W32: Punti | X32: =N34+N41+W27 -> 0 | AM32: Battuta | AN32: =B13 -> 0 | AO32: =G13 -> 0
B33: B# | C33: B+ | D33: B! | E33: B- | F33: B/ | G33: B= | H33: Tot | J33: Errori | K33: =G41+G34 -> 0 | N33: B# | O33: B+ | P33: B! | Q33: B- | R33: B/ | S33: B= | T33: Tot | W33: Errori | X33: =S41+S34 -> 0 | AM33: Attacco | AN33: =B20 -> 4 | AO33: =G20 -> 0
B34: =COUNTIF(B137:AG137,B33) -> 0 | C34: =COUNTIF(B137:AG137,C33) -> 0 | D34: =COUNTIF(B137:AG137,D33) -> 0 | E34: =COUNTIF(B137:AG137,E33) -> 0 | F34: =COUNTIF(C137:AH137,F33) -> 0 | G34: =COUNTIF(B137:AG137,G33) -> 0 | H34: =SUM(B34:G34) -> 0 | J34: Err. Ric | K34: =G27 -> 0 | N34: =COUNTIF(B138:AG138,N33) -> 0 | O34: =COUNTIF(B138:AG138,O33) -> 0 | P34: =COUNTIF(C138:AH138,P33) -> 0 | Q34: =COUNTIF(B138:AG138,Q33) -> 0 | R34: =COUNTIF(B138:AG138,R33) -> 0 | S34: =COUNTIF(B138:AG138,S33) -> 0 | T34: =SUM(N34:S34) -> 0 | W34: Err. Ric | X34: =S27 -> 0 | AM34: Muro | AN34: =J6 -> 1 | AO34: =K6 -> 0
B35: =IF($H$34>0,B34/$H$34,0) -> 0 | C35: =IF($H$34>0,C34/$H$34,0) -> 0 | D35: =IF($H$34>0,D34/$H$34,0) -> 0 | E35: =IF($H$34>0,E34/$H$34,0) -> 0 | F35: =IF($H$34>0,F34/$H$34,0) -> 0 | G35: =IF($H$34>0,G34/$H$34,0) -> 0 | H35: =SUM(B35:G35) -> 0 | J35: Eff. Ric | K35: =B29 -> 0 | N35: =IF($G$69>0,O34/$H$34,0) -> 0 | O35: =IF($G$69>0,Q34/$H$34,0) -> 0 | P35: =IF($G$69>0,R34/$H$34,0) -> 0 | Q35: =IF($G$69>0,S34/$H$34,0) -> 0 | R35: =IF($G$69>0,T34/$H$34,0) -> 0 | S35: =IF($G$69>0,T34/$H$34,0) -> 0 | W35: Eff. Ric | X35: =N29 -> 0 | AM35: Palleggio | AO35: =K8 -> 1
A36: Efficenza | B36: =IF(H34>0,(B34-G34)/H34,0) -> 0 | J36: Eff. Att. | K36: =B43 -> 0.5 | M36: Efficenza | N36: =IF(T34>0,(N34-S34)/T34,0) -> 0 | W36: Eff. Att. | X36: =N43 -> 0
A37: Positività | B37: =IF(H34>0,(B34+C34)/H34,0) -> 0 | I37: Muri sub | J37: =F41 -> 0 | M37: Positività | N37: =IF(T34>0,(N34+O34)/T34,0) -> 0 | U37: Muri sub | W37: =R41 -> 0
AM38: VINTI-PERSI
B39: Attacco | N39: Attacco | AM39: =K17 -> 4
B40: A# | C40: A+ | D40: A! | E40: A- | F40: A/ | G40: A= | H40: Tot | N40: A# | O40: A+ | P40: A! | Q40: A- | R40: A/ | S40: A= | T40: Tot
B41: =COUNTIF(B137:AG137,B40) -> 1 | C41: =COUNTIF(B137:AG137,C40) -> 0 | D41: =COUNTIF(B137:AG137,D40) -> 0 | E41: =COUNTIF(B137:AG137,E40) -> 1 | F41: =COUNTIF(B137:AG137,F40) -> 0 | G41: =COUNTIF(B137:AG137,G40) -> 0 | H41: =SUM(B41:G41) -> 2 | N41: =COUNTIF(B138:AG138,N40) -> 0 | O41: =COUNTIF(B138:AG138,O40) -> 0 | P41: =COUNTIF(B138:AG138,P40) -> 0 | Q41: =COUNTIF(B138:AG138,Q40) -> 0 | R41: =COUNTIF(B138:AG138,R40) -> 0 | S41: =COUNTIF(B138:AG138,S40) -> 0 | T41: =SUM(N41:S41) -> 0
...

Sheet Gioc C
A1: Giocatore N° | B1: =Atleti!B5 -> 13 | C1: =Atleti!D5 -> Giorgia Trodani
M2: SET1
A3: PARTITA | N3: Ricezione | W3: Muro
B4: Ricezione | J4: Muro | N4: R# | O4: R+ | P4: R! | Q4: R- | R4: R/ | S4: R= | T4: Tot | W4: M# | X4: M=
B5: R# | C5: R+ | D5: R! | E5: R- | F5: R/ | G5: R= | H5: Tot | J5: M# | K5: M= | N5: =COUNTIF(B136:AG136,N4) -> 0 | O5: =COUNTIF(B136:AG136,O4) -> 0 | P5: =COUNTIF(B136:AG136,P4) -> 0 | Q5: =COUNTIF(C136:AH136,Q4) -> 0 | R5: =COUNTIF(B136:AG136,R4) -> 0 | S5: =COUNTIF(B136:AG136,S4) -> 0 | T5: =SUM(N5:S5) -> 0 | W5: =COUNTIF(B136:AG136,W4) -> 0 | X5: =COUNTIF(B136:AG136,X4) -> 0
B6: =COUNTIF(B136:AG140,B5) -> 0 | C6: =COUNTIF(B136:AG140,C5) -> 0 | D6: =COUNTIF(B136:AG140,D5) -> 0 | E6: =COUNTIF(B136:AG140,E5) -> 0 | F6: =COUNTIF(B136:AG140,F5) -> 0 | G6: =COUNTIF(B136:AG140,G5) -> 0 | H6: =SUM(B6:G6) -> 0 | J6: =COUNTIF(B136:AG140,J5) -> 0 | K6: =COUNTIF(B136:AG140,K5) -> 0 | N6: =IF(T5>0,N5/T5,0) -> 0 | O6: =IF(T5>0,O5/T5,0) -> 0 | P6: =IF(T5>0,P5/T5,0) -> 0 | Q6: =IF(U5>0,Q5/U5,0) -> 0 | R6: =IF(T5>0,R5/T5,0) -> 0 | S6: =IF(T5>0,S5/T5,0) -> 0 | T6: =SUM(N6:S6) -> 0
B7: =IF(H6>0,B6/H6,0) -> 0 | C7: =IF(H6>0,C6/H6,0) -> 0 | D7: =IF(H6>0,D6/H6,0) -> 0 | E7: =IF(H6>0,E6/H6,0) -> 0 | F7: =IF(F6>0,F6/H6,0) -> 0 | G7: =IF(G6>0,G6/H6,0) -> 0 | H7: =SUM(B7:G7) -> 0 | M7: Efficenza | N7: =IF(T5>0,(N5-S5)/T5,0) -> 0
A8: Efficenza | B8: =IF(H6>0,(B6-G6)/H6,0) -> 0 | J8: P= | K8: =COUNTIF(B136:AG140,J8) -> 0 | M8: Positività | N8: =IF(T5>0,(N5+O5+P5)/T5,0) -> 0
A9: Positività | B9: =IF(H6>0,(B6+C6+D6)/H6,0) -> 0 | W9: Riassunto
J10: Riassunto | N10: Battuta | W10: Punti | X10: =N12+N19+W5 -> 0
B11: Battuta | J11: Punti | K11: =B13+B20+J6 -> 0 | N11: B# | O11: B+ | P11: B! | Q11: B- | R11: B/ | S11: B= | T11: Tot | W11: Errori | X11: =S19+S12 -> 0
B12: B# | C12: B/ | D12: B+ | E12: B! | F12: B- | G12: B= | H12: Tot | J12: Errori | K12: =G20+G13+K6+K8 -> 0 | N12: =COUNTIF(B136:AG136,N11) -> 0 | O12: =COUNTIF(B136:AG136,O11) -> 0 | P12: =COUNTIF(B136:AG136,P11) -> 0 | Q12: =COUNTIF(C136:AH136,Q11) -> 0 | R12: =COUNTIF(B136:AG136,R11) -> 0 | S12: =COUNTIF(B136:AG136,S11) -> 0 | T12: =SUM(N12:S12) -> 0 | W12: Err. Ric | X12: =S5 -> 0
B13: =COUNTIF(B136:AG140,B12) -> 0 | C13: =COUNTIF(B136:AG140,C12) -> 0 | D13: =COUNTIF(B136:AG140,D12) -> 0 | E13: =COUNTIF(C136:AH140,E12) -> 0 | F13: =COUNTIF(B136:AG140,F12) -> 0 | G13: =COUNTIF(B136:AG140,G12) -> 0 | H13: =SUM(B13:G13) -> 0 | J13: Err. Ric | K13: =G6 -> 0 | N13: =IF(T12>0,N12/T12,0) -> 0 | O13: =IF(S2>0,O12/T12,0) -> 0 | P13: =IF(T12>0,P12/T12,0) -> 0 | Q13: =IF(U12>0,Q12/U12,0) -> 0 | R13: =IF(S2>0,R12/T12,0) -> 0 | S13: =IF(S2>0,S12/T12,0) -> 0 | T13: =SUM(N13:S13) -> 0 | W13: Muri sub | X13: =R19 -> 0
B14: =IF(H13>0,B13/H13,0) -> 0 | C14: =IF(H13>0,C13/H13,0) -> 0 | D14: =IF(H13>0,D13/H13,0) -> 0 | E14: =IF(I13>0,E13/I13,0) -> 0 | F14: =IF(H13>0,F13/H13,0) -> 0 | G14: =IF(H13>0,G13/H13,0) -> 0 | H14: =SUM(B14:G14) -> 0 | J14: Muri sub | K14: =F20 -> 0 | M14: Efficenza | N14: =IF(T12>0,(N12-S12)/T12,0) -> 0 | W14: Eff. Ric | X14: =N7 -> 0
A15: Efficenza | B15: =IF(H13>0,(B13-G13)/H13,0) -> 0 | J15: Eff. Ric | K15: =B8 -> 0 | M15: Positività | N15: =IF(T12>0,(N12+O12)/T12,0) -> 0 | W15: Eff. Att. | X15: =N21 -> 0
A16: Efficacia | B16: =IF(H13>0,(B13+C13)/H13,0) -> 0 | J16: Eff. Att. | K16: =B22 -> 0
J17: V-P | K17: =K11-K12-K13 -> 0 | N17: Attacco
B18: Attacco | N18: A# | O18: A+ | P18: A! | Q18: A- | R18: A/ | S18: A= | T18: Tot
B19: A# | C19: A+ | D19: A! | E19: A- | F19: A/ | G19: A= | H19: Tot | N19: =COUNTIF(B136:AG136,N18) -> 0 | O19: =COUNTIF(B136:AG136,O18) -> 0 | P19: =COUNTIF(B136:AG136,P18) -> 0 | Q19: =COUNTIF(B136:AG136,Q18) -> 0 | R19: =COUNTIF(B136:AG136,R18) -> 0 | S19: =COUNTIF(B136:AG136,S18) -> 0 | T19: =SUM(N19:S19) -> 0
B20: =COUNTIF(B136:AG140,B19) -> 0 | C20: =COUNTIF(B136:AG140,C19) -> 0 | D20: =COUNTIF(B136:AG140,D19) -> 0 | E20: =COUNTIF(B136:AG140,E19) -> 0 | F20: =COUNTIF(B136:AG140,F19) -> 0 | G20: =COUNTIF(B136:AG140,G19) -> 0 | H20: =SUM(B20:G20) -> 0 | N20: =IF(T19>0,N19/T19,0) -> 0 | O20: =IF(T19>0,O19/T19,0) -> 0 | P20: =IF(T19>0,P19/T19,0) -> 0 | Q20: =IF(T19>0,Q19/T19,0) -> 0 | R20: =IF(T19>0,R19/T19,0) -> 0 | S20: =IF(T19>0,S19/T19,0) -> 0 | T20: =SUM(N20:S20) -> 0
B21: =IF(H20>0,B20/H20,0) -> 0 | C21: =IF(H20>0,C20/H20,0) -> 0 | D21: =IF(H20>0,D20/H20,0) -> 0 | E21: =IF(H20>0,E20/H20,0) -> 0 | F21: =IF(H20>0,F20/H20,0) -> 0 | G21: =IF(H20>0,G20/H20,0) -> 0 | H21: =SUM(B21:G21) -> 0 | M21: Efficenza | N21: =IF(T19>0,(N19-S19)/T19,0) -> 0
A22: Efficenza | B22: =IF(H20>0,(B20-G20)/H20,0) -> 0 | M22: Positività | N22: =IF(T19>0,(N19+O19+P19+Q19)/T19,0) -> 0
A23: Positività | B23: =IF(H20>0,(B20+C20+D20+E20)/H20,0) -> 0
A25: SET2 | B25: Ricezione | J25: Muro | M25: SET3 | N25: Ricezione | W25: Muro
